File: Modulus_Steel.csv
Time,Displacement,Force,Strain 1
(s),(mm),(kN),(%)
0.0000,0.0000,0.0060,0.0000
0.0200,0.0001,0.0058,0.0000
0.0400,0.0002,0.0057,-0.0001
0.0600,0.0004,0.0064,0.0000
0.0800,0.0006,0.0081,0.0001
0.1000,0.0010,0.0103,0.0002
0.1200,0.0014,0.0136,0.0003
0.1400,0.0020,0.0177,0.0004
0.1600,0.0024,0.0222,0.0005
0.1800,0.0028,0.0264,0.0007
0.2000,0.0032,0.0302,0.0008
0.2200,0.0035,0.0338,0.0010
0.2400,0.0038,0.0370,0.0011
0.2600,0.0041,0.0398,0.0012
0.2800,0.0044,0.0425,0.0013
0.3000,0.0047,0.0451,0.0014
0.3200,0.0050,0.0476,0.0015
0.3400,0.0054,0.0501,0.0016
0.3600,0.0058,0.0531,0.0018
0.3800,0.0062,0.0568,0.0019
0.4000,0.0067,0.0609,0.0020
0.4200,0.0071,0.0650,0.0022
0.4400,0.0075,0.0687,0.0024
0.4600,0.0078,0.0723,0.0024
0.4800,0.0081,0.0755,0.0026
0.5000,0.0084,0.0782,0.0027
0.5200,0.0087,0.0809,0.0028
0.5400,0.0089,0.0832,0.0029
0.5600,0.0092,0.0853,0.0029
0.5800,0.0095,0.0876,0.0031
0.6000,0.0098,0.0900,0.0032
0.6200,0.0101,0.0925,0.0032
0.6400,0.0104,0.0951,0.0033
0.6600,0.0109,0.0981,0.0034
0.6800,0.0113,0.1014,0.0035
0.7000,0.0117,0.1052,0.0037
0.7200,0.0121,0.1090,0.0038
0.7400,0.0125,0.1126,0.0040
0.7600,0.0128,0.1156,0.0040
0.7800,0.0131,0.1183,0.0041
0.8000,0.0134,0.1211,0.0042
0.8200,0.0137,0.1235,0.0043
0.8400,0.0140,0.1260,0.0044
0.8600,0.0142,0.1285,0.0045
0.8800,0.0145,0.1309,0.0046
0.9000,0.0148,0.1334,0.0047
0.9200,0.0151,0.1357,0.0048
0.9400,0.0154,0.1382,0.0049
0.9600,0.0158,0.1409,0.0050
0.9800,0.0162,0.1442,0.0051
1.0000,0.0167,0.1480,0.0052
1.0200,0.0171,0.1520,0.0054
1.0400,0.0176,0.1557,0.0055
1.0600,0.0179,0.1591,0.0056
1.0800,0.0182,0.1620,0.0057
1.1000,0.0185,0.1645,0.0058
1.1200,0.0187,0.1668,0.0059
1.1400,0.0190,0.1688,0.0060
1.1600,0.0193,0.1709,0.0061
1.1800,0.0195,0.1731,0.0062
1.2000,0.0198,0.1751,0.0063
1.2200,0.0201,0.1772,0.0064
1.2400,0.0204,0.1795,0.0064
1.2600,0.0208,0.1823,0.0065
1.2800,0.0213,0.1858,0.0066
1.3000,0.0217,0.1895,0.0068
1.3200,0.0221,0.1932,0.0069
1.3400,0.0225,0.1969,0.0071
1.3600,0.0229,0.2004,0.0072
1.3800,0.0231,0.2033,0.0073
1.4000,0.0235,0.2057,0.0074
1.4200,0.0237,0.2081,0.0075
1.4400,0.0241,0.2104,0.0076
1.4600,0.0243,0.2126,0.0077
1.4800,0.0246,0.2149,0.0078
1.5000,0.0249,0.2172,0.0079
1.5200,0.0251,0.2194,0.0080
1.5400,0.0254,0.2215,0.0080
1.5600,0.0258,0.2239,0.0081
1.5800,0.0262,0.2267,0.0082
1.6000,0.0267,0.2302,0.0083
1.6200,0.0271,0.2341,0.0085
1.6400,0.0275,0.2381,0.0086
1.6600,0.0279,0.2417,0.0087
1.6800,0.0282,0.2450,0.0089
1.7000,0.0285,0.2477,0.0090
1.7200,0.0288,0.2499,0.0091
1.7400,0.0290,0.2522,0.0092
1.7600,0.0293,0.2546,0.0092
1.7800,0.0295,0.2567,0.0093
1.8000,0.0298,0.2588,0.0094
1.8200,0.0301,0.2609,0.0095
1.8400,0.0304,0.2632,0.0096
1.8600,0.0308,0.2660,0.0097
1.8800,0.0312,0.2693,0.0098
1.9000,0.0317,0.2729,0.0099
1.9200,0.0321,0.2768,0.0100
1.9400,0.0325,0.2807,0.0102
1.9600,0.0329,0.2843,0.0103
1.9800,0.0332,0.2876,0.0104
2.0000,0.0335,0.2905,0.0105
2.0200,0.0338,0.2929,0.0107
2.0400,0.0341,0.2954,0.0107
2.0600,0.0344,0.2977,0.0109
2.0800,0.0347,0.3002,0.0110
2.1000,0.0349,0.3024,0.0110
2.1200,0.0352,0.3047,0.0111
2.1400,0.0355,0.3070,0.0112
2.1600,0.0358,0.3094,0.0113
2.1800,0.0362,0.3122,0.0114
2.2000,0.0366,0.3157,0.0115
2.2200,0.0371,0.3195,0.0116
2.2400,0.0375,0.3237,0.0118
2.2600,0.0379,0.3278,0.0120
2.2800,0.0382,0.3313,0.0121
2.3000,0.0385,0.3342,0.0122
2.3200,0.0388,0.3369,0.0122
2.3400,0.0391,0.3395,0.0123
2.3600,0.0394,0.3420,0.0124
2.3800,0.0396,0.3443,0.0125
2.4000,0.0399,0.3464,0.0127
2.4200,0.0401,0.3485,0.0127
2.4400,0.0404,0.3507,0.0128
2.4600,0.0408,0.3532,0.0129
2.4800,0.0411,0.3561,0.0130
2.5000,0.0416,0.3598,0.0131
2.5200,0.0421,0.3637,0.0132
2.5400,0.0425,0.3677,0.0134
2.5600,0.0429,0.3719,0.0135
2.5800,0.0432,0.3755,0.0137
2.6000,0.0436,0.3787,0.0138
2.6200,0.0439,0.3815,0.0139
2.6400,0.0441,0.3843,0.0140
2.6600,0.0444,0.3869,0.0140
2.6800,0.0447,0.3895,0.0142
2.7000,0.0449,0.3918,0.0143
2.7200,0.0452,0.3940,0.0144
2.7400,0.0455,0.3960,0.0144
2.7600,0.0457,0.3982,0.0145
2.7800,0.0461,0.4008,0.0146
2.8000,0.0465,0.4036,0.0147
2.8200,0.0469,0.4070,0.0148
2.8400,0.0474,0.4109,0.0150
2.8600,0.0478,0.4149,0.0151
2.8800,0.0482,0.4188,0.0153
2.9000,0.0485,0.4222,0.0154
2.9200,0.0488,0.4253,0.0155
2.9400,0.0491,0.4281,0.0156
2.9600,0.0494,0.4307,0.0157
2.9800,0.0497,0.4332,0.0158
3.0000,0.0499,0.4354,0.0159
3.0200,0.0502,0.4376,0.0160
3.0400,0.0505,0.4400,0.0161
3.0600,0.0508,0.4425,0.0161
3.0800,0.0511,0.4452,0.0162
3.1000,0.0515,0.4486,0.0163
3.1200,0.0520,0.4525,0.0164
3.1400,0.0524,0.4566,0.0166
3.1600,0.0529,0.4608,0.0167
3.1800,0.0532,0.4646,0.0169
3.2000,0.0536,0.4679,0.0170
3.2200,0.0539,0.4709,0.0171
3.2400,0.0542,0.4735,0.0172
3.2600,0.0544,0.4758,0.0173
3.2800,0.0547,0.4783,0.0174
3.3000,0.0550,0.4805,0.0175
3.3200,0.0552,0.4828,0.0176
3.3400,0.0555,0.4851,0.0177
3.3600,0.0558,0.4875,0.0177
3.3800,0.0561,0.4898,0.0178
3.4000,0.0564,0.4926,0.0179
3.4200,0.0568,0.4957,0.0181
3.4400,0.0573,0.4996,0.0182
3.4600,0.0577,0.5039,0.0183
3.4800,0.0581,0.5081,0.0184
3.5000,0.0585,0.5118,0.0186
3.5200,0.0588,0.5153,0.0187
3.5400,0.0591,0.5184,0.0188
3.5600,0.0595,0.5213,0.0189
3.5800,0.0597,0.5240,0.0190
3.6000,0.0600,0.5266,0.0191
3.6200,0.0603,0.5289,0.0191
3.6400,0.0605,0.5311,0.0192
3.6600,0.0608,0.5333,0.0193
3.6800,0.0611,0.5358,0.0195
3.7000,0.0615,0.5386,0.0196
3.7200,0.0619,0.5421,0.0197
3.7400,0.0624,0.5460,0.0198
3.7600,0.0628,0.5504,0.0199
3.7800,0.0632,0.5547,0.0201
3.8000,0.0635,0.5584,0.0202
3.8200,0.0638,0.5615,0.0203
3.8400,0.0641,0.5645,0.0204
3.8600,0.0644,0.5672,0.0205
3.8800,0.0647,0.5698,0.0206
3.9000,0.0650,0.5723,0.0207
3.9200,0.0652,0.5748,0.0208
3.9400,0.0655,0.5772,0.0209
3.9600,0.0658,0.5795,0.0210
3.9800,0.0661,0.5820,0.0210
4.0000,0.0664,0.5846,0.0211
4.0200,0.0668,0.5876,0.0212
4.0400,0.0672,0.5913,0.0213
4.0600,0.0677,0.5955,0.0215
4.0800,0.0681,0.5999,0.0216
4.1000,0.0685,0.6040,0.0217
4.1200,0.0688,0.6079,0.0218
4.1400,0.0692,0.6112,0.0219
4.1600,0.0695,0.6141,0.0221
4.1800,0.0697,0.6169,0.0222
4.2000,0.0700,0.6194,0.0222
4.2200,0.0703,0.6218,0.0224
4.2400,0.0706,0.6242,0.0224
4.2600,0.0709,0.6266,0.0225
4.2800,0.0711,0.6292,0.0226
4.3000,0.0715,0.6320,0.0227
4.3200,0.0719,0.6351,0.0228
4.3400,0.0723,0.6388,0.0229
4.3600,0.0727,0.6431,0.0230
4.3800,0.0731,0.6472,0.0231
4.4000,0.0734,0.6511,0.0233
4.4200,0.0738,0.6547,0.0234
4.4400,0.0741,0.6579,0.0235
4.4600,0.0745,0.6609,0.0236
4.4800,0.0747,0.6637,0.0237
4.5000,0.0751,0.6665,0.0238
4.5200,0.0753,0.6690,0.0239
4.5400,0.0756,0.6715,0.0239
4.5600,0.0759,0.6741,0.0240
4.5800,0.0761,0.6765,0.0241
4.6000,0.0764,0.6791,0.0241
4.6200,0.0768,0.6819,0.0243
4.6400,0.0772,0.6853,0.0244
4.6600,0.0776,0.6893,0.0245
4.6800,0.0781,0.6938,0.0246
4.7000,0.0785,0.6981,0.0248
4.7200,0.0789,0.7023,0.0249
4.7400,0.0792,0.7060,0.0250
4.7600,0.0796,0.7096,0.0251
4.7800,0.0798,0.7126,0.0252
4.8000,0.0801,0.7153,0.0253
4.8200,0.0804,0.7177,0.0254
4.8400,0.0806,0.7201,0.0255
4.8600,0.0809,0.7225,0.0256
4.8800,0.0812,0.7247,0.0256
4.9000,0.0814,0.7271,0.0257
4.9200,0.0818,0.7299,0.0258
4.9400,0.0822,0.7331,0.0259
4.9600,0.0827,0.7371,0.0260
4.9800,0.0831,0.7415,0.0262
5.0000,0.0835,0.7458,0.0263
5.0200,0.0838,0.7498,0.0264
5.0400,0.0841,0.7535,0.0265
5.0600,0.0845,0.7566,0.0266
5.0800,0.0848,0.7596,0.0267
5.1000,0.0851,0.7628,0.0268
5.1200,0.0854,0.7658,0.0269
5.1400,0.0857,0.7685,0.0270
5.1600,0.0859,0.7710,0.0271
5.1800,0.0862,0.7732,0.0271
5.2000,0.0865,0.7757,0.0272
5.2200,0.0868,0.7785,0.0273
5.2400,0.0872,0.7815,0.0274
5.2600,0.0876,0.7853,0.0275
5.2800,0.0881,0.7895,0.0277
5.3000,0.0885,0.7939,0.0278
5.3200,0.0889,0.7981,0.0279
5.3400,0.0892,0.8019,0.0280
5.3600,0.0896,0.8055,0.0281
5.3800,0.0898,0.8087,0.0282
5.4000,0.0901,0.8116,0.0284
5.4200,0.0904,0.8144,0.0285
5.4400,0.0906,0.8169,0.0285
5.4600,0.0909,0.8191,0.0286
5.4800,0.0911,0.8217,0.0287
5.5000,0.0914,0.8241,0.0288
5.5200,0.0918,0.8267,0.0288
5.5400,0.0921,0.8298,0.0289
5.5600,0.0926,0.8335,0.0290
5.5800,0.0930,0.8378,0.0291
5.6000,0.0934,0.8423,0.0293
5.6200,0.0938,0.8467,0.0294
5.6400,0.0941,0.8505,0.0295
5.6600,0.0945,0.8538,0.0296
5.6800,0.0948,0.8569,0.0297
5.7000,0.0951,0.8600,0.0298
5.7200,0.0954,0.8631,0.0299
5.7400,0.0957,0.8660,0.0300
5.7600,0.0959,0.8685,0.0301
5.7800,0.0962,0.8710,0.0302
5.8000,0.0965,0.8735,0.0303
5.8200,0.0968,0.8763,0.0304
5.8400,0.0971,0.8793,0.0304
5.8600,0.0976,0.8826,0.0305
5.8800,0.0980,0.8868,0.0306
5.9000,0.0985,0.8915,0.0308
5.9200,0.0988,0.8961,0.0309
5.9400,0.0992,0.8999,0.0310
5.9600,0.0995,0.9034,0.0311
5.9800,0.0998,0.9066,0.0312
6.0000,0.1001,0.9095,0.0313
6.0200,0.1004,0.9123,0.0314
6.0400,0.1007,0.9149,0.0315
6.0600,0.1009,0.9173,0.0316
6.0800,0.1011,0.9198,0.0317
6.1000,0.1015,0.9223,0.0318
6.1200,0.1017,0.9249,0.0319
6.1400,0.1021,0.9277,0.0319
6.1600,0.1025,0.9312,0.0320
6.1800,0.1030,0.9356,0.0321
6.2000,0.1034,0.9403,0.0323
6.2200,0.1038,0.9450,0.0324
6.2400,0.1042,0.9495,0.0325
6.2600,0.1045,0.9533,0.0326
6.2800,0.1048,0.9564,0.0327
6.3000,0.1052,0.9593,0.0328
6.3200,0.1054,0.9622,0.0329
6.3400,0.1057,0.9651,0.0330
6.3600,0.1060,0.9679,0.0331
6.3800,0.1062,0.9705,0.0332
6.4000,0.1065,0.9730,0.0332
6.4200,0.1068,0.9755,0.0333
6.4400,0.1071,0.9780,0.0334
6.4600,0.1075,0.9812,0.0335
6.4800,0.1079,0.9849,0.0336
6.5000,0.1084,0.9892,0.0338
6.5200,0.1087,0.9937,0.0339
6.5400,0.1091,0.9979,0.0340
6.5600,0.1095,1.0019,0.0341
6.5800,0.1098,1.0056,0.0342
6.6000,0.1101,1.0090,0.0343
6.6200,0.1104,1.0121,0.0344
6.6400,0.1107,1.0150,0.0345
6.6600,0.1109,1.0175,0.0346
6.6800,0.1112,1.0200,0.0347
6.7000,0.1115,1.0228,0.0347
6.7200,0.1117,1.0252,0.0348
6.7400,0.1121,1.0277,0.0349
6.7600,0.1124,1.0310,0.0350
6.7800,0.1129,1.0349,0.0351
6.8000,0.1134,1.0394,0.0352
6.8200,0.1138,1.0441,0.0353
6.8400,0.1142,1.0487,0.0355
6.8600,0.1145,1.0526,0.0356
6.8800,0.1149,1.0560,0.0357
6.9000,0.1152,1.0592,0.0358
6.9200,0.1155,1.0626,0.0359
6.9400,0.1158,1.0656,0.0360
6.9600,0.1160,1.0684,0.0361
6.9800,0.1163,1.0710,0.0362
7.0000,0.1165,1.0735,0.0362
7.0200,0.1168,1.0759,0.0363
7.0400,0.1171,1.0782,0.0364
7.0600,0.1174,1.0810,0.0365
7.0800,0.1178,1.0843,0.0366
7.1000,0.1182,1.0884,0.0367
7.1200,0.1187,1.0930,0.0368
7.1400,0.1191,1.0975,0.0369
7.1600,0.1195,1.1019,0.0371
7.1800,0.1198,1.1058,0.0372
7.2000,0.1201,1.1094,0.0373
7.2200,0.1204,1.1124,0.0374
7.2400,0.1207,1.1152,0.0374
7.2600,0.1210,1.1182,0.0375
7.2800,0.1213,1.1209,0.0376
7.3000,0.1216,1.1234,0.0377
7.3200,0.1218,1.1260,0.0378
7.3400,0.1221,1.1287,0.0379
7.3600,0.1225,1.1318,0.0380
7.3800,0.1229,1.1356,0.0381
7.4000,0.1233,1.1398,0.0382
7.4200,0.1238,1.1446,0.0383
7.4400,0.1242,1.1494,0.0384
7.4600,0.1246,1.1539,0.0386
7.4800,0.1249,1.1577,0.0387
7.5000,0.1252,1.1609,0.0388
7.5200,0.1255,1.1637,0.0389
7.5400,0.1257,1.1663,0.0389
7.5600,0.1260,1.1688,0.0390
7.5800,0.1263,1.1713,0.0391
7.6000,0.1265,1.1740,0.0392
7.6200,0.1268,1.1765,0.0393
7.6400,0.1271,1.1792,0.0393
7.6600,0.1274,1.1818,0.0394
7.6800,0.1278,1.1852,0.0396
7.7000,0.1282,1.1890,0.0396
7.7200,0.1286,1.1935,0.0398
7.7400,0.1291,1.1983,0.0399
7.7600,0.1295,1.2030,0.0400
7.7800,0.1299,1.2071,0.0401
7.8000,0.1302,1.2111,0.0403
7.8200,0.1305,1.2146,0.0404
7.8400,0.1308,1.2175,0.0404
7.8600,0.1310,1.2205,0.0405
7.8800,0.1313,1.2232,0.0406
7.9000,0.1316,1.2257,0.0407
7.9200,0.1318,1.2280,0.0408
7.9400,0.1321,1.2304,0.0408
7.9600,0.1324,1.2331,0.0409
7.9800,0.1329,1.2365,0.0410
8.0000,0.1333,1.2405,0.0412
8.0200,0.1337,1.2451,0.0413
8.0400,0.1341,1.2500,0.0414
8.0600,0.1345,1.2547,0.0415
8.0800,0.1348,1.2588,0.0416
8.1000,0.1352,1.2622,0.0417
8.1200,0.1354,1.2653,0.0418
8.1400,0.1357,1.2682,0.0419
8.1600,0.1360,1.2710,0.0420
8.1800,0.1363,1.2738,0.0421
8.2000,0.1366,1.2765,0.0421
8.2200,0.1369,1.2793,0.0422
8.2400,0.1371,1.2819,0.0423
8.2600,0.1374,1.2846,0.0424
8.2800,0.1378,1.2874,0.0425
8.3000,0.1382,1.2909,0.0426
8.3200,0.1386,1.2952,0.0427
8.3400,0.1391,1.2999,0.0429
8.3600,0.1394,1.3048,0.0430
8.3800,0.1399,1.3091,0.0431
8.4000,0.1402,1.3133,0.0433
8.4200,0.1405,1.3172,0.0433
8.4400,0.1408,1.3208,0.0434
8.4600,0.1411,1.3238,0.0435
8.4800,0.1414,1.3265,0.0436
8.5000,0.1416,1.3291,0.0437
8.5200,0.1419,1.3319,0.0438
8.5400,0.1422,1.3343,0.0439
8.5600,0.1424,1.3367,0.0439
8.5800,0.1428,1.3395,0.0440
8.6000,0.1432,1.3430,0.0441
8.6200,0.1436,1.3472,0.0442
8.6400,0.1441,1.3517,0.0443
8.6600,0.1445,1.3566,0.0445
8.6800,0.1448,1.3610,0.0446
8.7000,0.1451,1.3648,0.0447
8.7200,0.1454,1.3679,0.0448
8.7400,0.1458,1.3710,0.0449
8.7600,0.1461,1.3743,0.0450
8.7800,0.1464,1.3774,0.0450
8.8000,0.1466,1.3805,0.0451
8.8200,0.1469,1.3833,0.0453
8.8400,0.1472,1.3860,0.0454
8.8600,0.1475,1.3886,0.0455
8.8800,0.1477,1.3913,0.0455
8.9000,0.1481,1.3945,0.0456
8.9200,0.1486,1.3982,0.0457
8.9400,0.1490,1.4026,0.0458
8.9600,0.1494,1.4074,0.0459
8.9800,0.1498,1.4122,0.0461
9.0000,0.1502,1.4165,0.0462
9.0200,0.1506,1.4206,0.0463
9.0400,0.1509,1.4243,0.0464
9.0600,0.1512,1.4276,0.0465
9.0800,0.1514,1.4305,0.0466
9.1000,0.1517,1.4332,0.0467
9.1200,0.1519,1.4357,0.0468
9.1400,0.1522,1.4381,0.0468
9.1600,0.1525,1.4406,0.0469
9.1800,0.1527,1.4431,0.0470
9.2000,0.1531,1.4464,0.0470
9.2200,0.1535,1.4502,0.0472
9.2400,0.1540,1.4543,0.0473
9.2600,0.1544,1.4592,0.0474
9.2800,0.1548,1.4640,0.0475
9.3000,0.1551,1.4684,0.0477
9.3200,0.1555,1.4723,0.0478
9.3400,0.1558,1.4755,0.0478
9.3600,0.1561,1.4785,0.0479
9.3800,0.1564,1.4816,0.0481
9.4000,0.1567,1.4847,0.0481
9.4200,0.1570,1.4877,0.0482
9.4400,0.1572,1.4904,0.0483
9.4600,0.1575,1.4933,0.0484
9.4800,0.1578,1.4960,0.0485
9.5000,0.1581,1.4988,0.0486
9.5200,0.1585,1.5019,0.0487
9.5400,0.1589,1.5056,0.0488
9.5600,0.1594,1.5104,0.0489
9.5800,0.1598,1.5155,0.0490
9.6000,0.1602,1.5204,0.0491
9.6200,0.1606,1.5249,0.0492
9.6400,0.1609,1.5288,0.0494
9.6600,0.1612,1.5322,0.0495
9.6800,0.1615,1.5352,0.0495
9.7000,0.1617,1.5379,0.0496
9.7200,0.1619,1.5404,0.0497
9.7400,0.1622,1.5428,0.0498
9.7600,0.1625,1.5452,0.0498
9.7800,0.1627,1.5476,0.0499
9.8000,0.1631,1.5503,0.0500
9.8200,0.1634,1.5537,0.0501
9.8400,0.1639,1.5578,0.0502
9.8600,0.1643,1.5625,0.0504
9.8800,0.1647,1.5675,0.0505
9.9000,0.1652,1.5725,0.0506
9.9200,0.1655,1.5769,0.0508
9.9400,0.1658,1.5806,0.0508
9.9600,0.1661,1.5839,0.0509
9.9800,0.1664,1.5870,0.0510
10.0000,0.1667,1.5900,0.0511
10.0200,0.1670,1.5929,0.0512
10.0400,0.1673,1.5959,0.0512
10.0600,0.1676,1.5987,0.0513
10.0800,0.1678,1.6015,0.0515
10.1000,0.1681,1.6041,0.0515
10.1200,0.1685,1.6070,0.0516
10.1400,0.1689,1.6106,0.0517
10.1600,0.1693,1.6147,0.0518
10.1800,0.1698,1.6194,0.0519
10.2000,0.1701,1.6244,0.0520
10.2200,0.1705,1.6292,0.0522
10.2400,0.1708,1.6332,0.0523
10.2600,0.1712,1.6367,0.0524
10.2800,0.1714,1.6397,0.0525
10.3000,0.1717,1.6424,0.0526
10.3200,0.1720,1.6454,0.0526
10.3400,0.1722,1.6483,0.0527
10.3600,0.1725,1.6509,0.0528
10.3800,0.1728,1.6534,0.0529
10.4000,0.1731,1.6561,0.0530
10.4200,0.1734,1.6591,0.0530
10.4400,0.1738,1.6626,0.0531
10.4600,0.1743,1.6667,0.0533
10.4800,0.1747,1.6716,0.0534
10.5000,0.1751,1.6768,0.0535
10.5200,0.1755,1.6816,0.0537
10.5400,0.1759,1.6858,0.0538
10.5600,0.1762,1.6894,0.0539
10.5800,0.1765,1.6927,0.0540
10.6000,0.1768,1.6961,0.0541
10.6200,0.1771,1.6994,0.0542
10.6400,0.1774,1.7023,0.0543
10.6600,0.1776,1.7050,0.0543
10.6800,0.1779,1.7076,0.0544
10.7000,0.1781,1.7103,0.0545
10.7200,0.1784,1.7131,0.0545
10.7400,0.1788,1.7161,0.0547
10.7600,0.1791,1.7194,0.0548
10.7800,0.1796,1.7236,0.0549
10.8000,0.1801,1.7284,0.0550
10.8200,0.1804,1.7334,0.0551
10.8400,0.1808,1.7380,0.0552
10.8600,0.1811,1.7419,0.0553
10.8800,0.1814,1.7456,0.0554
10.9000,0.1818,1.7491,0.0555
10.9200,0.1820,1.7524,0.0556
10.9400,0.1823,1.7555,0.0557
10.9600,0.1826,1.7583,0.0558
10.9800,0.1828,1.7610,0.0559
11.0000,0.1831,1.7637,0.0559
11.0200,0.1834,1.7666,0.0560
11.0400,0.1838,1.7696,0.0561
11.0600,0.1842,1.7735,0.0562
11.0800,0.1847,1.7781,0.0563
11.1000,0.1851,1.7832,0.0565
11.1200,0.1855,1.7882,0.0566
11.1400,0.1859,1.7929,0.0568
11.1600,0.1862,1.7969,0.0569
11.1800,0.1865,1.8003,0.0569
11.2000,0.1869,1.8035,0.0570
11.2200,0.1871,1.8066,0.0571
11.2400,0.1874,1.8096,0.0572
11.2600,0.1877,1.8125,0.0573
11.2800,0.1879,1.8152,0.0574
11.3000,0.1881,1.8179,0.0575
11.3200,0.1884,1.8204,0.0576
11.3400,0.1888,1.8232,0.0576
11.3600,0.1891,1.8267,0.0576
11.3800,0.1895,1.8308,0.0578
11.4000,0.1900,1.8354,0.0579
11.4200,0.1904,1.8403,0.0581
11.4400,0.1908,1.8452,0.0582
11.4600,0.1911,1.8497,0.0583
11.4800,0.1915,1.8537,0.0584
11.5000,0.1918,1.8575,0.0585
11.5200,0.1921,1.8607,0.0586
11.5400,0.1924,1.8638,0.0587
11.5600,0.1926,1.8668,0.0588
11.5800,0.1929,1.8695,0.0588
11.6000,0.1932,1.8722,0.0589
11.6200,0.1934,1.8748,0.0590
11.6400,0.1938,1.8777,0.0591
11.6600,0.1942,1.8813,0.0592
11.6800,0.1946,1.8856,0.0593
11.7000,0.1951,1.8907,0.0595
11.7200,0.1955,1.8960,0.0596
11.7400,0.1959,1.9011,0.0597
11.7600,0.1962,1.9056,0.0598
11.7800,0.1966,1.9092,0.0599
11.8000,0.1968,1.9123,0.0600
11.8200,0.1971,1.9153,0.0601
11.8400,0.1974,1.9183,0.0602
11.8600,0.1977,1.9214,0.0603
11.8800,0.1979,1.9242,0.0604
11.9000,0.1982,1.9267,0.0604
11.9200,0.1984,1.9292,0.0605
11.9400,0.1987,1.9320,0.0606
11.9600,0.1991,1.9350,0.0607
11.9800,0.1994,1.9386,0.0607
12.0000,0.1999,1.9431,0.0609
12.0200,0.2004,1.9481,0.0610
12.0400,0.2008,1.9535,0.0611
12.0600,0.2012,1.9583,0.0613
12.0800,0.2015,1.9627,0.0614
12.1000,0.2019,1.9666,0.0615
12.1200,0.2021,1.9703,0.0616
12.1400,0.2024,1.9734,0.0617
12.1600,0.2027,1.9763,0.0618
12.1800,0.2029,1.9791,0.0619
12.2000,0.2032,1.9818,0.0620
12.2200,0.2035,1.9842,0.0620
12.2400,0.2038,1.9867,0.0621
12.2600,0.2042,1.9900,0.0621
12.2800,0.2046,1.9941,0.0622
12.3000,0.2050,1.9987,0.0624
12.3200,0.2054,2.0038,0.0625
12.3400,0.2058,2.0092,0.0627
12.3600,0.2062,2.0139,0.0628
12.3800,0.2065,2.0179,0.0629
12.4000,0.2068,2.0215,0.0630
12.4200,0.2071,2.0245,0.0631
12.4400,0.2074,2.0275,0.0632
12.4600,0.2077,2.0307,0.0633
12.4800,0.2080,2.0336,0.0634
12.5000,0.2082,2.0363,0.0635
12.5200,0.2085,2.0392,0.0635
12.5400,0.2088,2.0418,0.0636
12.5600,0.2090,2.0445,0.0637
12.5800,0.2094,2.0480,0.0638
12.6000,0.2098,2.0518,0.0639
12.6200,0.2103,2.0563,0.0640
12.6400,0.2107,2.0616,0.0641
12.6600,0.2111,2.0670,0.0643
12.6800,0.2115,2.0720,0.0644
12.7000,0.2119,2.0763,0.0645
12.7200,0.2122,2.0801,0.0646
12.7400,0.2125,2.0838,0.0647
12.7600,0.2127,2.0868,0.0648
12.7800,0.2130,2.0895,0.0649
12.8000,0.2133,2.0921,0.0649
12.8200,0.2135,2.0945,0.0650
12.8400,0.2138,2.0971,0.0651
12.8600,0.2141,2.0999,0.0651
12.8800,0.2145,2.1035,0.0653
12.9000,0.2149,2.1078,0.0654
12.9200,0.2154,2.1127,0.0655
12.9400,0.2158,2.1177,0.0656
12.9600,0.2162,2.1226,0.0658
12.9800,0.2165,2.1272,0.0659
13.0000,0.2168,2.1310,0.0660
13.0200,0.2171,2.1345,0.0661
13.0400,0.2174,2.1380,0.0662
13.0600,0.2177,2.1411,0.0663
13.0800,0.2180,2.1441,0.0664
13.1000,0.2182,2.1471,0.0665
13.1200,0.2185,2.1499,0.0665
13.1400,0.2188,2.1528,0.0666
13.1600,0.2191,2.1557,0.0667
13.1800,0.2194,2.1586,0.0667
13.2000,0.2198,2.1620,0.0668
13.2200,0.2202,2.1661,0.0670
13.2400,0.2207,2.1708,0.0671
13.2600,0.2211,2.1762,0.0672
13.2800,0.2215,2.1816,0.0674
13.3000,0.2219,2.1864,0.0675
13.3200,0.2222,2.1906,0.0676
13.3400,0.2225,2.1943,0.0677
13.3600,0.2228,2.1973,0.0678
13.3800,0.2231,2.2002,0.0679
13.4000,0.2233,2.2031,0.0680
13.4200,0.2236,2.2059,0.0681
13.4400,0.2238,2.2086,0.0681
13.4600,0.2241,2.2113,0.0682
13.4800,0.2244,2.2141,0.0683
13.5000,0.2248,2.2173,0.0684
13.5200,0.2253,2.2215,0.0685
13.5400,0.2257,2.2264,0.0687
13.5600,0.2261,2.2317,0.0688
13.5800,0.2265,2.2368,0.0689
13.6000,0.2268,2.2410,0.0690
13.6200,0.2271,2.2448,0.0691
13.6400,0.2275,2.2481,0.0693
13.6600,0.2277,2.2514,0.0693
13.6800,0.2280,2.2548,0.0694
13.7000,0.2283,2.2580,0.0695
13.7200,0.2286,2.2609,0.0696
13.7400,0.2289,2.2638,0.0697
13.7600,0.2291,2.2668,0.0697
13.7800,0.2294,2.2698,0.0698
13.8000,0.2298,2.2729,0.0699
13.8200,0.2302,2.2767,0.0700
13.8400,0.2306,2.2813,0.0701
13.8600,0.2311,2.2867,0.0703
13.8800,0.2315,2.2922,0.0704
13.9000,0.2319,2.2974,0.0705
13.9200,0.2322,2.3018,0.0707
13.9400,0.2325,2.3054,0.0708
13.9600,0.2328,2.3083,0.0709
13.9800,0.2331,2.3112,0.0710
14.0000,0.2333,2.3138,0.0710
14.0200,0.2336,2.3166,0.0711
14.0400,0.2338,2.3196,0.0712
14.0600,0.2341,2.3223,0.0712
14.0800,0.2344,2.3252,0.0713
14.1000,0.2347,2.3284,0.0714
14.1200,0.2352,2.3323,0.0715
14.1400,0.2356,2.3372,0.0716
14.1600,0.2361,2.3428,0.0718
14.1800,0.2365,2.3482,0.0719
14.2000,0.2368,2.3531,0.0720
14.2200,0.2372,2.3574,0.0722
14.2400,0.2375,2.3613,0.0723
14.2600,0.2378,2.3646,0.0724
14.2800,0.2381,2.3678,0.0725
14.3000,0.2384,2.3710,0.0726
14.3200,0.2387,2.3741,0.0726
14.3400,0.2389,2.3770,0.0728
14.3600,0.2392,2.3798,0.0728
14.3800,0.2395,2.3828,0.0729
14.4000,0.2398,2.3859,0.0730
14.4200,0.2402,2.3894,0.0731
14.4400,0.2406,2.3936,0.0732
14.4600,0.2411,2.3986,0.0733
14.4800,0.2415,2.4041,0.0734
14.5000,0.2419,2.4094,0.0736
14.5200,0.2422,2.4140,0.0737
14.5400,0.2425,2.4177,0.0738
14.5600,0.2428,2.4209,0.0739
14.5800,0.2431,2.4239,0.0740
14.6000,0.2434,2.4269,0.0741
14.6200,0.2436,2.4299,0.0742
14.6400,0.2439,2.4328,0.0742
14.6600,0.2441,2.4355,0.0743
14.6800,0.2444,2.4384,0.0744
14.7000,0.2448,2.4416,0.0745
14.7200,0.2451,2.4454,0.0746
14.7400,0.2456,2.4498,0.0747
14.7600,0.2461,2.4550,0.0748
14.7800,0.2465,2.4606,0.0750
14.8000,0.2469,2.4659,0.0751
14.8200,0.2472,2.4706,0.0752
14.8400,0.2476,2.4747,0.0753
14.8600,0.2478,2.4781,0.0754
14.8800,0.2481,2.4811,0.0756
14.9000,0.2484,2.4841,0.0756
14.9200,0.2487,2.4873,0.0757
14.9400,0.2489,2.4903,0.0757
14.9600,0.2492,2.4934,0.0758
14.9800,0.2495,2.4964,0.0759
15.0000,0.2498,2.4994,0.0760
15.0200,0.2501,2.5024,0.0761
15.0400,0.2505,2.5059,0.0762
15.0600,0.2509,2.5102,0.0762
15.0800,0.2514,2.5154,0.0764
15.1000,0.2518,2.5210,0.0766
15.1200,0.2522,2.5262,0.0767
15.1400,0.2525,2.5306,0.0768
15.1600,0.2528,2.5344,0.0769
15.1800,0.2531,2.5377,0.0770
15.2000,0.2534,2.5408,0.0771
15.2200,0.2537,2.5439,0.0772
15.2400,0.2539,2.5470,0.0772
15.2600,0.2542,2.5499,0.0773
15.2800,0.2545,2.5527,0.0774
15.3000,0.2547,2.5554,0.0775
15.3200,0.2551,2.5585,0.0776
15.3400,0.2555,2.5627,0.0777
15.3600,0.2560,2.5675,0.0778
15.3800,0.2564,2.5728,0.0780
15.4000,0.2568,2.5785,0.0781
15.4200,0.2572,2.5839,0.0782
15.4400,0.2576,2.5885,0.0784
15.4600,0.2579,2.5922,0.0785
15.4800,0.2582,2.5955,0.0786
15.5000,0.2585,2.5987,0.0787
15.5200,0.2587,2.6018,0.0787
15.5400,0.2590,2.6048,0.0788
15.5600,0.2593,2.6078,0.0789
15.5800,0.2595,2.6105,0.0790
15.6000,0.2598,2.6134,0.0790
15.6200,0.2601,2.6161,0.0791
15.6400,0.2604,2.6191,0.0792
15.6600,0.2608,2.6228,0.0793
15.6800,0.2613,2.6273,0.0795
15.7000,0.2617,2.6328,0.0796
15.7200,0.2621,2.6384,0.0797
15.7400,0.2624,2.6436,0.0798
15.7600,0.2628,2.6482,0.0799
15.7800,0.2631,2.6519,0.0800
15.8000,0.2634,2.6553,0.0802
15.8200,0.2637,2.6587,0.0803
15.8400,0.2639,2.6617,0.0803
15.8600,0.2642,2.6646,0.0804
15.8800,0.2645,2.6672,0.0805
15.9000,0.2647,2.6700,0.0805
15.9200,0.2651,2.6730,0.0806
15.9400,0.2655,2.6765,0.0807
15.9600,0.2659,2.6807,0.0808
15.9800,0.2664,2.6856,0.0810
16.0000,0.2668,2.6911,0.0811
16.0200,0.2672,2.6967,0.0812
16.0400,0.2675,2.7018,0.0814
16.0600,0.2679,2.7061,0.0815
16.0800,0.2682,2.7097,0.0816
16.1000,0.2684,2.7130,0.0817
16.1200,0.2687,2.7160,0.0818
16.1400,0.2690,2.7189,0.0819
16.1600,0.2693,2.7219,0.0820
16.1800,0.2696,2.7248,0.0820
16.2000,0.2698,2.7276,0.0821
16.2200,0.2701,2.7304,0.0822
16.2400,0.2704,2.7334,0.0823
16.2600,0.2708,2.7370,0.0823
16.2800,0.2712,2.7414,0.0824
16.3000,0.2717,2.7467,0.0826
16.3200,0.2721,2.7525,0.0828
16.3400,0.2725,2.7579,0.0829
16.3600,0.2728,2.7626,0.0830
16.3800,0.2732,2.7667,0.0831
16.4000,0.2735,2.7704,0.0832
16.4200,0.2737,2.7737,0.0833
16.4400,0.2740,2.7769,0.0834
16.4600,0.2743,2.7800,0.0835
16.4800,0.2746,2.7828,0.0836
16.5000,0.2749,2.7855,0.0837
16.5200,0.2751,2.7886,0.0838
16.5400,0.2755,2.7918,0.0838
16.5600,0.2758,2.7956,0.0839
16.5800,0.2763,2.8001,0.0840
16.6000,0.2768,2.8055,0.0842
16.6200,0.2772,2.8113,0.0844
16.6400,0.2776,2.8166,0.0845
16.6600,0.2778,2.8208,0.0846
16.6800,0.2781,2.8244,0.0847
16.7000,0.2785,2.8277,0.0848
16.7200,0.2787,2.8311,0.0849
16.7400,0.2791,2.8344,0.0850
16.7600,0.2793,2.8375,0.0851
16.7800,0.2795,2.8406,0.0851
16.8000,0.2798,2.8436,0.0852
16.8200,0.2801,2.8464,0.0853
16.8400,0.2804,2.8493,0.0853
16.8600,0.2808,2.8529,0.0854
16.8800,0.2811,2.8570,0.0855
16.9000,0.2816,2.8618,0.0857
16.9200,0.2821,2.8672,0.0858
16.9400,0.2825,2.8728,0.0860
16.9600,0.2829,2.8782,0.0861
16.9800,0.2832,2.8828,0.0862
17.0000,0.2835,2.8868,0.0863
17.0200,0.2838,2.8903,0.0864
17.0400,0.2841,2.8936,0.0865
17.0600,0.2844,2.8967,0.0866
17.0800,0.2846,2.8997,0.0866
17.1000,0.2849,2.9026,0.0867
17.1200,0.2852,2.9055,0.0868
17.1400,0.2855,2.9085,0.0869
17.1600,0.2859,2.9119,0.0870
17.1800,0.2862,2.9159,0.0871
17.2000,0.2867,2.9203,0.0872
17.2200,0.2870,2.9254,0.0874
17.2400,0.2874,2.9305,0.0875
17.2600,0.2878,2.9354,0.0876
17.2800,0.2882,2.9397,0.0877
17.3000,0.2885,2.9437,0.0878
17.3200,0.2888,2.9476,0.0879
17.3400,0.2891,2.9514,0.0880
17.3600,0.2893,2.9549,0.0881
17.3800,0.2896,2.9580,0.0882
17.4000,0.2899,2.9610,0.0883
17.4200,0.2901,2.9640,0.0884
17.4400,0.2905,2.9671,0.0885
17.4600,0.2908,2.9702,0.0885
17.4800,0.2912,2.9736,0.0886
17.5000,0.2916,2.9780,0.0887
17.5200,0.2920,2.9831,0.0889
17.5400,0.2924,2.9885,0.0890
17.5600,0.2928,2.9936,0.0891
17.5800,0.2932,2.9985,0.0893
17.6000,0.2936,3.0031,0.0894
17.6200,0.2938,3.0072,0.0895
17.6400,0.2942,3.0110,0.0896
17.6600,0.2944,3.0142,0.0897
17.6800,0.2947,3.0172,0.0897
17.7000,0.2949,3.0201,0.0898
17.7200,0.2952,3.0227,0.0899
17.7400,0.2954,3.0253,0.0900
17.7600,0.2958,3.0282,0.0901
17.7800,0.2961,3.0317,0.0902
17.8000,0.2965,3.0360,0.0903
17.8200,0.2969,3.0408,0.0904
17.8400,0.2974,3.0461,0.0905
17.8600,0.2977,3.0514,0.0907
17.8800,0.2981,3.0565,0.0908
17.9000,0.2984,3.0607,0.0909
17.9200,0.2988,3.0647,0.0909
17.9400,0.2991,3.0685,0.0910
17.9600,0.2994,3.0721,0.0912
17.9800,0.2997,3.0756,0.0913
18.0000,0.3000,3.0788,0.0914
18.0200,0.3002,3.0819,0.0915
18.0400,0.3005,3.0850,0.0915
18.0600,0.3008,3.0878,0.0916
18.0800,0.3011,3.0909,0.0917
18.1000,0.3015,3.0945,0.0918
18.1200,0.3020,3.0991,0.0919
18.1400,0.3024,3.1047,0.0920
18.1600,0.3028,3.1102,0.0922
18.1800,0.3032,3.1151,0.0923
18.2000,0.3035,3.1195,0.0924
18.2200,0.3039,3.1236,0.0925
18.2400,0.3042,3.1274,0.0926
18.2600,0.3044,3.1308,0.0927
18.2800,0.3047,3.1339,0.0928
18.3000,0.3049,3.1369,0.0929
18.3200,0.3052,3.1397,0.0930
18.3400,0.3055,3.1426,0.0930
18.3600,0.3058,3.1453,0.0931
18.3800,0.3061,3.1485,0.0932
18.4000,0.3065,3.1523,0.0933
18.4200,0.3069,3.1568,0.0934
18.4400,0.3074,3.1623,0.0936
18.4600,0.3078,3.1681,0.0937
18.4800,0.3081,3.1732,0.0939
18.5000,0.3085,3.1778,0.0940
18.5200,0.3088,3.1817,0.0940
18.5400,0.3091,3.1852,0.0941
18.5600,0.3094,3.1890,0.0942
18.5800,0.3097,3.1926,0.0943
18.6000,0.3100,3.1962,0.0944
18.6200,0.3103,3.1993,0.0945
18.6400,0.3106,3.2024,0.0946
18.6600,0.3108,3.2054,0.0947
18.6800,0.3111,3.2085,0.0948
18.7000,0.3115,3.2119,0.0948
18.7200,0.3119,3.2161,0.0949
18.7400,0.3124,3.2212,0.0951
18.7600,0.3127,3.2269,0.0952
18.7800,0.3131,3.2319,0.0953
18.8000,0.3135,3.2362,0.0955
18.8200,0.3138,3.2403,0.0956
18.8400,0.3141,3.2441,0.0957
18.8600,0.3144,3.2477,0.0958
18.8800,0.3147,3.2509,0.0959
18.9000,0.3149,3.2543,0.0959
18.9200,0.3152,3.2574,0.0960
18.9400,0.3155,3.2604,0.0961
18.9600,0.3158,3.2635,0.0962
18.9800,0.3161,3.2666,0.0963
19.0000,0.3164,3.2701,0.0963
19.0200,0.3169,3.2744,0.0965
19.0400,0.3173,3.2794,0.0966
19.0600,0.3178,3.2850,0.0967
19.0800,0.3182,3.2907,0.0968
19.1000,0.3185,3.2956,0.0970
19.1200,0.3189,3.3000,0.0971
19.1400,0.3191,3.3037,0.0972
19.1600,0.3194,3.3072,0.0973
19.1800,0.3198,3.3107,0.0974
19.2000,0.3201,3.3142,0.0975
19.2200,0.3204,3.3175,0.0976
19.2400,0.3206,3.3209,0.0977
19.2600,0.3208,3.3238,0.0978
19.2800,0.3212,3.3266,0.0978
19.3000,0.3215,3.3297,0.0979
19.3200,0.3219,3.3334,0.0980
19.3400,0.3223,3.3380,0.0981
19.3600,0.3227,3.3432,0.0982
19.3800,0.3231,3.3486,0.0984
19.4000,0.3235,3.3532,0.0985
19.4200,0.3238,3.3575,0.0986
19.4400,0.3241,3.3616,0.0987
19.4600,0.3244,3.3657,0.0987
19.4800,0.3247,3.3695,0.0988
19.5000,0.3250,3.3728,0.0990
19.5200,0.3253,3.3761,0.0991
19.5400,0.3256,3.3792,0.0991
19.5600,0.3258,3.3823,0.0992
19.5800,0.3261,3.3852,0.0993
19.6000,0.3264,3.3882,0.0994
19.6200,0.3268,3.3922,0.0995
19.6400,0.3273,3.3970,0.0996
19.6600,0.3277,3.4027,0.0998
19.6800,0.3282,3.4087,0.0999
19.7000,0.3285,3.4140,0.1000
19.7200,0.3289,3.4186,0.1001
19.7400,0.3292,3.4225,0.1003
19.7600,0.3295,3.4263,0.1004
19.7800,0.3298,3.4298,0.1005
19.8000,0.3301,3.4334,0.1006
19.8200,0.3304,3.4366,0.1006
19.8400,0.3306,3.4394,0.1007
19.8600,0.3309,3.4423,0.1008
19.8800,0.3311,3.4450,0.1009
19.9000,0.3314,3.4479,0.1009
19.9200,0.3318,3.4512,0.1010
19.9400,0.3322,3.4554,0.1011
19.9600,0.3326,3.4605,0.1013
19.9800,0.3331,3.4660,0.1014
20.0000,0.3335,3.4716,0.1016
20.0200,0.3338,3.4767,0.1017
20.0400,0.3341,3.4809,0.1018
20.0600,0.3344,3.4848,0.1019
20.0800,0.3348,3.4885,0.1020
20.1000,0.3350,3.4920,0.1021
20.1200,0.3353,3.4952,0.1022
20.1400,0.3356,3.4983,0.1022
20.1520,0.3357,3.5002,0.1023