File: Modulus_Al.csv
Time,Displacement,Force,Strain 1
(s),(mm),(kN),(%)
0.0000,0.0000,0.0095,-0.0024
0.0400,0.0001,0.0095,-0.0024
0.0800,0.0004,0.0096,-0.0024
0.1200,0.0010,0.0106,-0.0023
0.1600,0.0021,0.0131,-0.0022
0.2000,0.0031,0.0163,-0.0021
0.2400,0.0040,0.0188,-0.0021
0.2800,0.0046,0.0210,-0.0021
0.3200,0.0051,0.0226,-0.0021
0.3600,0.0058,0.0239,-0.0021
0.4000,0.0066,0.0259,-0.0021
0.4400,0.0076,0.0281,-0.0021
0.4800,0.0082,0.0299,-0.0021
0.5200,0.0088,0.0316,-0.0021
0.5600,0.0094,0.0332,-0.0021
0.6000,0.0100,0.0346,-0.0021
0.6400,0.0105,0.0358,-0.0021
0.6800,0.0111,0.0373,-0.0021
0.7200,0.0120,0.0390,-0.0021
0.7600,0.0129,0.0413,-0.0021
0.8000,0.0136,0.0430,-0.0022
0.8400,0.0142,0.0447,-0.0022
0.8800,0.0147,0.0462,-0.0022
0.9200,0.0153,0.0475,-0.0022
0.9600,0.0159,0.0488,-0.0022
1.0000,0.0167,0.0504,-0.0021
1.0400,0.0175,0.0528,-0.0022
1.0800,0.0182,0.0549,-0.0022
1.1200,0.0189,0.0565,-0.0022
1.1600,0.0195,0.0583,-0.0022
1.2000,0.0200,0.0597,-0.0022
1.2400,0.0206,0.0610,-0.0022
1.2800,0.0212,0.0625,-0.0021
1.3200,0.0220,0.0642,-0.0021
1.3600,0.0228,0.0668,-0.0021
1.4000,0.0236,0.0691,-0.0021
1.4400,0.0243,0.0711,-0.0021
1.4800,0.0248,0.0725,-0.0021
1.5200,0.0253,0.0739,-0.0021
1.5600,0.0259,0.0754,-0.0021
1.6000,0.0266,0.0772,-0.0021
1.6400,0.0274,0.0796,-0.0020
1.6800,0.0282,0.0822,-0.0020
1.7200,0.0289,0.0844,-0.0020
1.7600,0.0295,0.0863,-0.0020
1.8000,0.0301,0.0882,-0.0020
1.8400,0.0306,0.0900,-0.0020
1.8800,0.0312,0.0919,-0.0020
1.9200,0.0319,0.0939,-0.0019
1.9600,0.0328,0.0966,-0.0018
2.0000,0.0336,0.0994,-0.0018
2.0400,0.0343,0.1017,-0.0018
2.0800,0.0348,0.1038,-0.0017
2.1200,0.0353,0.1053,-0.0018
2.1600,0.0359,0.1070,-0.0017
2.2000,0.0365,0.1091,-0.0017
2.2400,0.0373,0.1116,-0.0016
2.2800,0.0382,0.1148,-0.0016
2.3200,0.0389,0.1174,-0.0015
2.3600,0.0395,0.1196,-0.0015
2.4000,0.0401,0.1217,-0.0015
2.4400,0.0407,0.1235,-0.0015
2.4800,0.0412,0.1252,-0.0015
2.5200,0.0419,0.1270,-0.0014
2.5600,0.0428,0.1298,-0.0014
2.6000,0.0436,0.1328,-0.0012
2.6400,0.0442,0.1352,-0.0012
2.6800,0.0448,0.1374,-0.0012
2.7200,0.0453,0.1389,-0.0012
2.7600,0.0459,0.1408,-0.0012
2.8000,0.0465,0.1426,-0.0012
2.8400,0.0473,0.1450,-0.0012
2.8800,0.0482,0.1480,-0.0010
2.9200,0.0489,0.1508,-0.0010
2.9600,0.0496,0.1530,-0.0010
3.0000,0.0501,0.1550,-0.0010
3.0400,0.0507,0.1567,-0.0009
3.0800,0.0513,0.1585,-0.0009
3.1200,0.0519,0.1606,-0.0009
3.1600,0.0527,0.1631,-0.0008
3.2000,0.0535,0.1660,-0.0007
3.2400,0.0542,0.1688,-0.0007
3.2800,0.0549,0.1709,-0.0006
3.3200,0.0554,0.1729,-0.0006
3.3600,0.0559,0.1749,-0.0006
3.4000,0.0565,0.1767,-0.0006
3.4400,0.0573,0.1788,-0.0005
3.4800,0.0582,0.1819,-0.0004
3.5200,0.0589,0.1851,-0.0003
3.5600,0.0596,0.1877,-0.0003
3.6000,0.0602,0.1897,-0.0002
3.6400,0.0607,0.1916,-0.0003
3.6800,0.0612,0.1931,-0.0003
3.7200,0.0618,0.1950,-0.0002
3.7600,0.0626,0.1971,-0.0002
3.8000,0.0634,0.2006,-0.0001
3.8400,0.0642,0.2035,0.0000
3.8800,0.0649,0.2060,0.0002
3.9200,0.0655,0.2079,0.0001
3.9600,0.0660,0.2101,0.0002
4.0000,0.0665,0.2116,0.0001
4.0400,0.0672,0.2140,0.0002
4.0800,0.0681,0.2171,0.0004
4.1200,0.0689,0.2205,0.0005
4.1600,0.0696,0.2233,0.0006
4.2000,0.0702,0.2258,0.0007
4.2400,0.0708,0.2275,0.0007
4.2800,0.0712,0.2294,0.0008
4.3200,0.0718,0.2311,0.0008
4.3600,0.0725,0.2337,0.0009
4.4000,0.0734,0.2370,0.0011
4.4400,0.0742,0.2405,0.0012
4.4800,0.0749,0.2436,0.0013
4.5200,0.0755,0.2461,0.0013
4.5600,0.0760,0.2483,0.0014
4.6000,0.0766,0.2500,0.0015
4.6400,0.0772,0.2519,0.0016
4.6800,0.0781,0.2549,0.0017
4.7200,0.0789,0.2588,0.0018
4.7600,0.0796,0.2619,0.0020
4.8000,0.0802,0.2644,0.0020
4.8400,0.0808,0.2663,0.0021
4.8800,0.0813,0.2684,0.0022
4.9200,0.0819,0.2703,0.0022
4.9600,0.0825,0.2727,0.0024
5.0000,0.0834,0.2758,0.0025
5.0400,0.0842,0.2794,0.0027
5.0800,0.0850,0.2829,0.0028
5.1200,0.0856,0.2855,0.0029
5.1600,0.0861,0.2875,0.0030
5.2000,0.0866,0.2897,0.0030
5.2400,0.0872,0.2918,0.0031
5.2800,0.0880,0.2944,0.0033
5.3200,0.0888,0.2983,0.0034
5.3600,0.0895,0.3018,0.0036
5.4000,0.0902,0.3045,0.0037
5.4400,0.0908,0.3070,0.0038
5.4800,0.0914,0.3092,0.0039
5.5200,0.0919,0.3113,0.0040
5.5600,0.0925,0.3137,0.0041
5.6000,0.0933,0.3166,0.0043
5.6400,0.0942,0.3205,0.0044
5.6800,0.0950,0.3241,0.0046
5.7200,0.0956,0.3271,0.0048
5.7600,0.0962,0.3295,0.0049
5.8000,0.0966,0.3315,0.0050
5.8400,0.0972,0.3334,0.0051
5.8800,0.0979,0.3358,0.0052
5.9200,0.0987,0.3394,0.0054
5.9600,0.0995,0.3434,0.0057
6.0000,0.1002,0.3467,0.0058
6.0400,0.1008,0.3492,0.0060
6.0800,0.1014,0.3520,0.0061
6.1200,0.1019,0.3541,0.0063
6.1600,0.1025,0.3564,0.0064
6.2000,0.1032,0.3594,0.0065
6.2400,0.1041,0.3633,0.0068
6.2800,0.1049,0.3675,0.0071
6.3200,0.1056,0.3710,0.0073
6.3600,0.1062,0.3735,0.0074
6.4000,0.1067,0.3758,0.0076
6.4400,0.1072,0.3779,0.0077
6.4800,0.1078,0.3806,0.0079
6.5200,0.1086,0.3839,0.0080
6.5600,0.1095,0.3880,0.0083
6.6000,0.1102,0.3918,0.0086
6.6400,0.1109,0.3948,0.0088
6.6800,0.1115,0.3972,0.0089
6.7200,0.1120,0.4000,0.0091
6.7600,0.1126,0.4023,0.0093
6.8000,0.1132,0.4049,0.0094
6.8400,0.1141,0.4085,0.0096
6.8800,0.1149,0.4127,0.0099
6.9200,0.1156,0.4165,0.0102
6.9600,0.1161,0.4191,0.0103
7.0000,0.1167,0.4217,0.0105
7.0400,0.1172,0.4241,0.0106
7.0800,0.1178,0.4265,0.0108
7.1200,0.1186,0.4297,0.0110
7.1600,0.1195,0.4341,0.0113
7.2000,0.1203,0.4384,0.0116
7.2400,0.1209,0.4414,0.0118
7.2800,0.1216,0.4443,0.0119
7.3200,0.1220,0.4470,0.0121
7.3600,0.1226,0.4493,0.0123
7.4000,0.1232,0.4518,0.0124
7.4400,0.1240,0.4549,0.0127
7.4800,0.1248,0.4589,0.0129
7.5200,0.1255,0.4629,0.0132
7.5600,0.1262,0.4664,0.0134
7.6000,0.1267,0.4691,0.0136
7.6400,0.1273,0.4716,0.0137
7.6800,0.1279,0.4741,0.0139
7.7200,0.1286,0.4771,0.0141
7.7600,0.1294,0.4810,0.0144
7.8000,0.1303,0.4856,0.0147
7.8400,0.1309,0.4894,0.0149
7.8800,0.1316,0.4923,0.0151
7.9200,0.1321,0.4952,0.0153
7.9600,0.1326,0.4975,0.0154
8.0000,0.1332,0.4998,0.0156
8.0400,0.1339,0.5027,0.0158
8.0800,0.1347,0.5068,0.0161
8.1200,0.1355,0.5111,0.0163
8.1600,0.1362,0.5146,0.0166
8.2000,0.1368,0.5179,0.0168
8.2400,0.1374,0.5204,0.0170
8.2800,0.1379,0.5223,0.0171
8.3200,0.1385,0.5252,0.0173
8.3600,0.1394,0.5290,0.0175
8.4000,0.1403,0.5336,0.0178
8.4400,0.1409,0.5374,0.0181
8.4800,0.1415,0.5405,0.0183
8.5200,0.1421,0.5430,0.0184
8.5600,0.1426,0.5456,0.0186
8.6000,0.1432,0.5479,0.0188
8.6400,0.1438,0.5506,0.0189
8.6800,0.1447,0.5545,0.0192
8.7200,0.1455,0.5592,0.0195
8.7600,0.1462,0.5630,0.0198
8.8000,0.1469,0.5662,0.0200
8.8400,0.1474,0.5688,0.0201
8.8800,0.1479,0.5711,0.0203
8.9200,0.1486,0.5735,0.0204
8.9600,0.1494,0.5769,0.0206
9.0000,0.1502,0.5812,0.0209
9.0400,0.1509,0.5855,0.0212
9.0800,0.1516,0.5883,0.0214
9.1200,0.1521,0.5909,0.0215
9.1600,0.1527,0.5934,0.0217
9.2000,0.1532,0.5959,0.0218
9.2400,0.1538,0.5983,0.0220
9.2800,0.1546,0.6016,0.0222
9.3200,0.1555,0.6063,0.0225
9.3600,0.1563,0.6106,0.0228
9.4000,0.1569,0.6140,0.0230
9.4400,0.1575,0.6169,0.0231
9.4800,0.1580,0.6190,0.0233
9.5200,0.1585,0.6211,0.0234
9.5600,0.1593,0.6243,0.0236
9.6000,0.1601,0.6285,0.0239
9.6400,0.1609,0.6327,0.0241
9.6800,0.1615,0.6361,0.0243
9.7200,0.1622,0.6389,0.0245
9.7600,0.1627,0.6416,0.0247
9.8000,0.1632,0.6442,0.0248
9.8400,0.1638,0.6465,0.0249
9.8800,0.1646,0.6494,0.0251
9.9200,0.1655,0.6537,0.0254
9.9600,0.1663,0.6583,0.0257
10.0000,0.1669,0.6621,0.0259
10.0400,0.1675,0.6649,0.0261
10.0800,0.1681,0.6672,0.0262
10.1200,0.1685,0.6696,0.0264
10.1600,0.1692,0.6724,0.0265
10.2000,0.1700,0.6762,0.0268
10.2400,0.1708,0.6808,0.0270
10.2800,0.1715,0.6849,0.0273
10.3200,0.1722,0.6881,0.0275
10.3600,0.1728,0.6910,0.0277
10.4000,0.1733,0.6933,0.0278
10.4400,0.1738,0.6959,0.0279
10.4800,0.1745,0.6989,0.0281
10.5200,0.1754,0.7027,0.0284
10.5600,0.1763,0.7076,0.0288
10.6000,0.1769,0.7117,0.0290
10.6400,0.1775,0.7144,0.0292
10.6800,0.1780,0.7169,0.0293
10.7200,0.1786,0.7191,0.0294
10.7600,0.1791,0.7218,0.0296
10.8000,0.1799,0.7252,0.0298
10.8400,0.1809,0.7300,0.0301
10.8800,0.1816,0.7345,0.0304
10.9200,0.1822,0.7382,0.0306
10.9600,0.1828,0.7410,0.0308
11.0000,0.1834,0.7436,0.0309
11.0400,0.1839,0.7461,0.0311
11.0800,0.1845,0.7488,0.0313
11.1200,0.1854,0.7525,0.0315
11.1600,0.1863,0.7573,0.0318
11.2000,0.1869,0.7615,0.0321
11.2400,0.1875,0.7645,0.0323
11.2800,0.1881,0.7670,0.0324
11.3200,0.1886,0.7695,0.0326
11.3600,0.1892,0.7718,0.0327
11.4000,0.1899,0.7752,0.0330
11.4400,0.1908,0.7797,0.0333
11.4800,0.1916,0.7845,0.0336
11.5200,0.1923,0.7882,0.0338
11.5600,0.1929,0.7911,0.0340
11.6000,0.1934,0.7942,0.0342
11.6400,0.1940,0.7966,0.0343
11.6800,0.1945,0.7992,0.0344
11.7200,0.1953,0.8027,0.0347
11.7600,0.1961,0.8071,0.0350
11.8000,0.1969,0.8119,0.0353
11.8400,0.1975,0.8154,0.0355
11.8800,0.1981,0.8182,0.0357
11.9200,0.1986,0.8211,0.0359
11.9600,0.1992,0.8233,0.0360
12.0000,0.1999,0.8264,0.0362
12.0400,0.2007,0.8304,0.0365
12.0800,0.2016,0.8354,0.0368
12.1200,0.2023,0.8396,0.0371
12.1600,0.2029,0.8428,0.0373
12.2000,0.2035,0.8458,0.0375
12.2400,0.2040,0.8484,0.0376
12.2800,0.2045,0.8507,0.0378
12.3200,0.2052,0.8534,0.0379
12.3600,0.2060,0.8577,0.0382
12.4000,0.2068,0.8627,0.0386
12.4400,0.2075,0.8671,0.0389
12.4800,0.2081,0.8703,0.0390
12.5200,0.2087,0.8732,0.0392
12.5600,0.2092,0.8758,0.0394
12.6000,0.2098,0.8786,0.0396
12.6400,0.2107,0.8823,0.0398
12.6800,0.2116,0.8871,0.0401
12.7200,0.2123,0.8917,0.0404
12.7600,0.2129,0.8953,0.0407
12.8000,0.2135,0.8981,0.0408
12.8400,0.2140,0.9009,0.0410
12.8800,0.2146,0.9034,0.0412
12.9200,0.2151,0.9064,0.0413
12.9600,0.2160,0.9104,0.0416
13.0000,0.2168,0.9153,0.0419
13.0400,0.2176,0.9196,0.0423
13.0800,0.2182,0.9233,0.0425
13.1200,0.2188,0.9266,0.0427
13.1600,0.2193,0.9290,0.0428
13.2000,0.2199,0.9318,0.0430
13.2400,0.2207,0.9355,0.0432
13.2800,0.2215,0.9402,0.0435
13.3200,0.2223,0.9449,0.0439
13.3600,0.2229,0.9485,0.0441
13.4000,0.2235,0.9516,0.0443
13.4400,0.2240,0.9546,0.0445
13.4800,0.2245,0.9573,0.0446
13.5200,0.2252,0.9599,0.0448
13.5600,0.2259,0.9636,0.0451
13.6000,0.2268,0.9687,0.0454
13.6400,0.2276,0.9735,0.0457
13.6800,0.2282,0.9772,0.0459
13.7200,0.2288,0.9805,0.0461
13.7600,0.2293,0.9833,0.0463
13.8000,0.2299,0.9861,0.0465
13.8400,0.2306,0.9893,0.0467
13.8800,0.2314,0.9938,0.0470
13.9200,0.2322,0.9984,0.0473
13.9600,0.2329,1.0025,0.0476
14.0000,0.2335,1.0059,0.0477
14.0400,0.2341,1.0095,0.0480
14.0800,0.2346,1.0120,0.0481
14.1200,0.2352,1.0148,0.0483
14.1600,0.2359,1.0182,0.0485
14.2000,0.2368,1.0227,0.0488
14.2400,0.2376,1.0277,0.0491
14.2800,0.2383,1.0319,0.0494
14.3200,0.2389,1.0356,0.0497
14.3600,0.2394,1.0382,0.0498
14.4000,0.2399,1.0409,0.0500
14.4400,0.2405,1.0437,0.0501
14.4800,0.2413,1.0478,0.0504
14.5200,0.2421,1.0531,0.0507
14.5600,0.2428,1.0579,0.0510
14.6000,0.2435,1.0615,0.0513
14.6400,0.2441,1.0649,0.0515
14.6800,0.2447,1.0679,0.0517
14.7200,0.2452,1.0709,0.0518
14.7600,0.2459,1.0737,0.0520
14.8000,0.2467,1.0780,0.0523
14.8400,0.2476,1.0831,0.0526
14.8800,0.2483,1.0876,0.0529
14.9200,0.2489,1.0911,0.0532
14.9600,0.2494,1.0940,0.0533
15.0000,0.2499,1.0964,0.0534
15.0400,0.2505,1.0994,0.0536
15.0800,0.2512,1.1032,0.0539
15.1200,0.2522,1.1080,0.0542
15.1600,0.2529,1.1134,0.0546
15.2000,0.2536,1.1174,0.0548
15.2400,0.2541,1.1208,0.0550
15.2800,0.2547,1.1240,0.0552
15.3200,0.2553,1.1267,0.0554
15.3600,0.2559,1.1296,0.0555
15.4000,0.2567,1.1336,0.0558
15.4400,0.2575,1.1388,0.0561
15.4800,0.2582,1.1433,0.0564
15.5200,0.2589,1.1472,0.0567
15.5600,0.2594,1.1501,0.0569
15.6000,0.2599,1.1530,0.0570
15.6400,0.2605,1.1557,0.0572
15.6800,0.2612,1.1591,0.0574
15.7200,0.2621,1.1640,0.0577
15.7600,0.2629,1.1694,0.0581
15.8000,0.2636,1.1739,0.0584
15.8400,0.2642,1.1775,0.0586
15.8800,0.2648,1.1808,0.0588
15.9200,0.2653,1.1839,0.0589
15.9600,0.2659,1.1867,0.0591
16.0000,0.2666,1.1902,0.0593
16.0400,0.2674,1.1950,0.0597
16.0800,0.2682,1.1999,0.0600
16.1200,0.2689,1.2040,0.0602
16.1600,0.2695,1.2077,0.0604
16.2000,0.2700,1.2107,0.0607
16.2400,0.2705,1.2137,0.0608
16.2800,0.2712,1.2164,0.0610
16.3200,0.2720,1.2210,0.0613
16.3600,0.2729,1.2267,0.0617
16.4000,0.2736,1.2314,0.0620
16.4400,0.2742,1.2353,0.0622
16.4800,0.2748,1.2386,0.0625
16.5200,0.2753,1.2417,0.0626
16.5600,0.2758,1.2443,0.0628
16.6000,0.2765,1.2476,0.0630
16.6400,0.2774,1.2521,0.0633
16.6800,0.2782,1.2575,0.0636
16.7200,0.2788,1.2622,0.0640
16.7600,0.2795,1.2658,0.0642
16.8000,0.2800,1.2689,0.0644
16.8400,0.2806,1.2716,0.0645
16.8800,0.2812,1.2746,0.0648
16.9200,0.2820,1.2787,0.0650
16.9600,0.2829,1.2843,0.0654
17.0000,0.2836,1.2896,0.0657
17.0400,0.2842,1.2934,0.0659
17.0800,0.2848,1.2964,0.0661
17.1200,0.2853,1.2993,0.0663
17.1600,0.2859,1.3021,0.0664
17.2000,0.2865,1.3053,0.0666
17.2400,0.2873,1.3099,0.0669
17.2800,0.2882,1.3155,0.0672
17.3200,0.2889,1.3206,0.0676
17.3600,0.2896,1.3243,0.0679
17.4000,0.2901,1.3276,0.0681
17.4400,0.2906,1.3306,0.0683
17.4800,0.2912,1.3332,0.0684
17.5200,0.2920,1.3371,0.0686
17.5600,0.2929,1.3422,0.0690
17.6000,0.2936,1.3476,0.0693
17.6400,0.2942,1.3513,0.0696
17.6800,0.2948,1.3546,0.0698
17.7200,0.2954,1.3581,0.0700
17.7600,0.2959,1.3614,0.0701
17.8000,0.2965,1.3642,0.0703
17.8400,0.2973,1.3683,0.0706
17.8800,0.2981,1.3737,0.0709
17.9200,0.2989,1.3790,0.0713
17.9600,0.2996,1.3834,0.0715
18.0000,0.3002,1.3868,0.0718
18.0400,0.3007,1.3896,0.0719
18.0800,0.3012,1.3925,0.0721
18.1200,0.3019,1.3958,0.0723
18.1600,0.3027,1.4003,0.0726
18.2000,0.3035,1.4059,0.0730
18.2400,0.3042,1.4102,0.0733
18.2800,0.3048,1.4140,0.0735
18.3200,0.3054,1.4176,0.0737
18.3600,0.3059,1.4209,0.0739
18.4000,0.3065,1.4241,0.0740
18.4400,0.3072,1.4274,0.0743
18.4800,0.3081,1.4326,0.0746
18.5200,0.3089,1.4381,0.0749
18.5600,0.3096,1.4428,0.0752
18.6000,0.3102,1.4467,0.0755
18.6400,0.3108,1.4498,0.0757
18.6800,0.3112,1.4522,0.0758
18.7200,0.3118,1.4549,0.0760
18.7600,0.3126,1.4590,0.0762
18.8000,0.3135,1.4647,0.0766
18.8400,0.3142,1.4699,0.0769
18.8800,0.3148,1.4739,0.0772
18.9200,0.3155,1.4777,0.0774
18.9600,0.3160,1.4810,0.0776
19.0000,0.3166,1.4840,0.0778
19.0400,0.3172,1.4872,0.0780
19.0800,0.3181,1.4917,0.0782
19.1200,0.3189,1.4976,0.0786
19.1600,0.3196,1.5025,0.0789
19.2000,0.3202,1.5064,0.0792
19.2400,0.3207,1.5096,0.0793
19.2800,0.3213,1.5122,0.0795
19.3200,0.3218,1.5152,0.0797
19.3600,0.3226,1.5187,0.0799
19.4000,0.3235,1.5242,0.0802
19.4400,0.3242,1.5298,0.0806
19.4800,0.3249,1.5340,0.0809
19.5200,0.3255,1.5376,0.0811
19.5600,0.3260,1.5410,0.0813
19.6000,0.3266,1.5442,0.0815
19.6400,0.3272,1.5472,0.0816
19.6800,0.3280,1.5513,0.0819
19.7200,0.3289,1.5570,0.0822
19.7600,0.3296,1.5624,0.0825
19.8000,0.3302,1.5662,0.0828
19.8400,0.3307,1.5696,0.0830
19.8800,0.3313,1.5728,0.0831
19.9200,0.3318,1.5756,0.0833
19.9600,0.3325,1.5788,0.0835
20.0000,0.3334,1.5837,0.0838
20.0400,0.3342,1.5896,0.0842
20.0800,0.3349,1.5945,0.0845
20.1200,0.3356,1.5982,0.0847
20.1600,0.3361,1.6018,0.0849
20.2000,0.3366,1.6048,0.0851
20.2400,0.3372,1.6076,0.0852
20.2800,0.3379,1.6111,0.0854
20.3200,0.3387,1.6160,0.0858
20.3600,0.3395,1.6217,0.0861
20.4000,0.3402,1.6261,0.0864
20.4400,0.3408,1.6301,0.0866
20.4800,0.3414,1.6338,0.0868
20.5200,0.3419,1.6365,0.0870
20.5600,0.3425,1.6395,0.0871
20.6000,0.3433,1.6439,0.0874
20.6400,0.3442,1.6498,0.0878
20.6800,0.3449,1.6552,0.0881
20.7200,0.3456,1.6591,0.0883
20.7600,0.3462,1.6627,0.0885
20.8000,0.3467,1.6660,0.0887
20.8400,0.3472,1.6688,0.0889
20.8800,0.3478,1.6722,0.0891
20.9200,0.3486,1.6769,0.0893
20.9600,0.3495,1.6826,0.0898
21.0000,0.3502,1.6880,0.0901
21.0400,0.3509,1.6925,0.0903
21.0800,0.3514,1.6959,0.0905
21.1200,0.3520,1.6990,0.0907
21.1600,0.3526,1.7018,0.0909
21.2000,0.3533,1.7059,0.0911
21.2400,0.3542,1.7117,0.0915
21.2800,0.3550,1.7175,0.0919
21.3200,0.3556,1.7219,0.0922
21.3600,0.3562,1.7252,0.0923
21.4000,0.3567,1.7286,0.0925
21.4400,0.3572,1.7316,0.0927
21.4800,0.3578,1.7349,0.0929
21.5200,0.3586,1.7392,0.0931
21.5600,0.3595,1.7451,0.0935
21.6000,0.3602,1.7510,0.0939
21.6400,0.3609,1.7557,0.0942
21.6800,0.3615,1.7596,0.0944
21.7200,0.3620,1.7628,0.0946
21.7600,0.3625,1.7657,0.0947
21.8000,0.3633,1.7694,0.0950
21.8400,0.3642,1.7747,0.0953
21.8800,0.3649,1.7808,0.0957
21.9200,0.3656,1.7856,0.0960
21.9600,0.3662,1.7890,0.0962
22.0000,0.3667,1.7926,0.0964
22.0400,0.3672,1.7959,0.0967
22.0800,0.3678,1.7993,0.0968
22.1200,0.3685,1.8032,0.0971
22.1600,0.3694,1.8088,0.0974
22.2000,0.3702,1.8149,0.0978
22.2400,0.3709,1.8199,0.0981
22.2800,0.3715,1.8241,0.0984
22.3200,0.3721,1.8274,0.0986
22.3600,0.3726,1.8304,0.0988
22.4000,0.3732,1.8336,0.0989
22.4400,0.3740,1.8384,0.0993
22.4800,0.3748,1.8441,0.0996
22.5200,0.3755,1.8495,0.1000
22.5600,0.3762,1.8533,0.1002
22.6000,0.3768,1.8574,0.1004
22.6400,0.3773,1.8610,0.1007
22.6800,0.3778,1.8644,0.1008
22.7200,0.3785,1.8679,0.1011
22.7600,0.3793,1.8728,0.1014
22.8000,0.3802,1.8792,0.1018
22.8400,0.3809,1.8845,0.1021
22.8800,0.3815,1.8887,0.1024
22.9200,0.3821,1.8922,0.1026
22.9600,0.3826,1.8952,0.1028
23.0000,0.3832,1.8984,0.1029
23.0400,0.3839,1.9023,0.1032
23.0800,0.3848,1.9079,0.1036
23.1200,0.3856,1.9139,0.1039
23.1600,0.3862,1.9185,0.1042
23.2000,0.3868,1.9225,0.1045
23.2400,0.3873,1.9262,0.1047
23.2800,0.3879,1.9296,0.1049
23.3200,0.3885,1.9330,0.1051
23.3600,0.3893,1.9376,0.1054
23.4000,0.3902,1.9438,0.1058
23.4400,0.3910,1.9499,0.1062
23.4800,0.3916,1.9541,0.1065
23.5200,0.3921,1.9574,0.1067
23.5600,0.3926,1.9607,0.1068
23.6000,0.3932,1.9637,0.1070
23.6400,0.3939,1.9675,0.1072
23.6800,0.3948,1.9731,0.1076
23.7200,0.3956,1.9796,0.1080
23.7600,0.3963,1.9848,0.1083
23.8000,0.3969,1.9887,0.1086
23.8400,0.3974,1.9924,0.1088
23.8800,0.3979,1.9958,0.1090
23.9200,0.3985,1.9992,0.1092
23.9600,0.3993,2.0033,0.1094
24.0000,0.4002,2.0091,0.1098
24.0400,0.4009,2.0150,0.1102
24.0800,0.4015,2.0195,0.1106
24.1200,0.4021,2.0232,0.1108
24.1600,0.4026,2.0268,0.1109
24.2000,0.4032,2.0300,0.1111
24.2400,0.4039,2.0336,0.1114
24.2800,0.4047,2.0387,0.1117
24.3200,0.4056,2.0451,0.1121
24.3600,0.4063,2.0508,0.1125
24.4000,0.4069,2.0551,0.1127
24.4400,0.4075,2.0590,0.1129
24.4800,0.4080,2.0625,0.1132
24.5200,0.4086,2.0658,0.1134
24.5600,0.4092,2.0694,0.1135
24.6000,0.4101,2.0743,0.1139
24.6400,0.4109,2.0805,0.1143
24.6800,0.4115,2.0858,0.1146
24.7200,0.4121,2.0897,0.1149
24.7600,0.4127,2.0934,0.1151
24.8000,0.4132,2.0966,0.1153
24.8400,0.4138,2.0999,0.1155
24.8800,0.4146,2.1045,0.1158
24.9200,0.4155,2.1107,0.1162
24.9600,0.4162,2.1168,0.1166
25.0000,0.4169,2.1216,0.1169
25.0400,0.4175,2.1254,0.1171
25.0800,0.4181,2.1290,0.1173
25.1200,0.4186,2.1322,0.1175
25.1600,0.4191,2.1353,0.1177
25.2000,0.4199,2.1397,0.1180
25.2400,0.4208,2.1459,0.1184
25.2800,0.4216,2.1516,0.1188
25.3200,0.4221,2.1560,0.1190
25.3600,0.4227,2.1600,0.1193
25.4000,0.4233,2.1634,0.1195
25.4400,0.4238,2.1668,0.1196
25.4800,0.4246,2.1707,0.1199
25.5200,0.4255,2.1765,0.1203
25.5600,0.4263,2.1829,0.1207
25.6000,0.4269,2.1881,0.1211
25.6400,0.4275,2.1918,0.1212
25.6800,0.4280,2.1952,0.1215
25.7200,0.4286,2.1986,0.1216
25.7600,0.4292,2.2018,0.1218
25.8000,0.4299,2.2056,0.1221
25.8400,0.4308,2.2114,0.1224
25.8800,0.4315,2.2175,0.1229
25.9200,0.4322,2.2223,0.1232
25.9600,0.4328,2.2263,0.1235
26.0000,0.4333,2.2299,0.1237
26.0400,0.4339,2.2331,0.1238
26.0800,0.4346,2.2368,0.1240
26.1200,0.4354,2.2421,0.1244
26.1600,0.4363,2.2488,0.1248
26.2000,0.4369,2.2538,0.1251
26.2400,0.4375,2.2576,0.1254
26.2800,0.4381,2.2615,0.1256
26.3200,0.4386,2.2648,0.1258
26.3600,0.4392,2.2680,0.1260
26.4000,0.4399,2.2716,0.1262
26.4400,0.4407,2.2771,0.1266
26.4800,0.4415,2.2835,0.1270
26.5200,0.4422,2.2888,0.1273
26.5600,0.4429,2.2931,0.1276
26.6000,0.4434,2.2967,0.1278
26.6400,0.4439,2.3000,0.1280
26.6800,0.4446,2.3035,0.1282
26.7200,0.4453,2.3081,0.1284
26.7600,0.4461,2.3139,0.1288
26.8000,0.4469,2.3193,0.1292
26.8400,0.4475,2.3238,0.1295
26.8800,0.4481,2.3280,0.1297
26.9200,0.4487,2.3315,0.1300
26.9600,0.4492,2.3348,0.1302
27.0000,0.4498,2.3382,0.1304
27.0400,0.4507,2.3431,0.1307
27.0800,0.4515,2.3492,0.1311
27.1200,0.4523,2.3550,0.1314
27.1600,0.4529,2.3599,0.1318
27.2000,0.4535,2.3638,0.1319
27.2400,0.4540,2.3668,0.1322
27.2800,0.4545,2.3700,0.1323
27.3200,0.4552,2.3739,0.1325
27.3600,0.4561,2.3796,0.1329
27.4000,0.4569,2.3855,0.1333
27.4400,0.4576,2.3903,0.1336
27.4800,0.4581,2.3944,0.1339
27.5200,0.4587,2.3981,0.1341
27.5600,0.4593,2.4015,0.1343
27.6000,0.4599,2.4049,0.1345
27.6400,0.4607,2.4093,0.1348
27.6800,0.4615,2.4154,0.1352
27.7200,0.4623,2.4216,0.1355
27.7600,0.4629,2.4264,0.1359
27.8000,0.4634,2.4298,0.1361
27.8400,0.4640,2.4331,0.1363
27.8800,0.4645,2.4364,0.1364
27.9200,0.4652,2.4403,0.1367
27.9600,0.4660,2.4457,0.1371
28.0000,0.4669,2.4521,0.1374
28.0400,0.4675,2.4575,0.1378
28.0800,0.4682,2.4620,0.1381
28.1200,0.4687,2.4664,0.1384
28.1600,0.4693,2.4702,0.1386
28.2000,0.4699,2.4734,0.1388
28.2400,0.4706,2.4778,0.1391
28.2800,0.4715,2.4840,0.1395
28.3200,0.4722,2.4902,0.1399
28.3600,0.4729,2.4953,0.1402
28.4000,0.4735,2.4994,0.1405
28.4400,0.4740,2.5032,0.1407
28.4800,0.4745,2.5066,0.1410
28.5200,0.4751,2.5105,0.1412
28.5600,0.4760,2.5154,0.1415
28.6000,0.4768,2.5221,0.1420
28.6400,0.4776,2.5282,0.1424
28.6800,0.4782,2.5330,0.1427
28.7200,0.4788,2.5371,0.1430
28.7600,0.4794,2.5412,0.1432
28.8000,0.4799,2.5447,0.1434
28.8400,0.4806,2.5485,0.1437
28.8800,0.4814,2.5542,0.1441
28.9200,0.4822,2.5608,0.1445
28.9600,0.4828,2.5661,0.1449
29.0000,0.4835,2.5708,0.1452
29.0400,0.4840,2.5749,0.1454
29.0800,0.4846,2.5784,0.1456
29.1200,0.4851,2.5820,0.1459
29.1600,0.4859,2.5866,0.1462
29.2000,0.4869,2.5931,0.1466
29.2400,0.4876,2.6001,0.1471
29.2800,0.4883,2.6051,0.1474
29.3200,0.4889,2.6096,0.1477
29.3600,0.4894,2.6136,0.1479
29.4000,0.4899,2.6170,0.1481
29.4400,0.4905,2.6205,0.1484
29.4800,0.4913,2.6255,0.1487
29.5200,0.4922,2.6317,0.1491
29.5600,0.4929,2.6379,0.1496
29.6000,0.4935,2.6427,0.1499
29.6400,0.4941,2.6471,0.1501
29.6800,0.4946,2.6507,0.1504
29.7200,0.4952,2.6543,0.1506
29.7600,0.4959,2.6586,0.1509
29.8000,0.4969,2.6649,0.1513
29.8400,0.4977,2.6722,0.1518
29.8800,0.4983,2.6775,0.1522
29.9200,0.4989,2.6819,0.1524
29.9600,0.4994,2.6856,0.1527
30.0000,0.4999,2.6890,0.1528
30.0400,0.5005,2.6924,0.1531
30.0800,0.5012,2.6969,0.1534
30.1200,0.5021,2.7032,0.1538
30.1600,0.5029,2.7099,0.1543
30.2000,0.5036,2.7150,0.1546
30.2400,0.5042,2.7193,0.1549
30.2800,0.5047,2.7233,0.1552
30.3200,0.5052,2.7268,0.1554
30.3600,0.5059,2.7306,0.1556
30.4000,0.5068,2.7365,0.1560
30.4400,0.5076,2.7434,0.1565
30.4800,0.5082,2.7493,0.1569
30.5200,0.5088,2.7535,0.1572
30.5600,0.5094,2.7576,0.1574
30.6000,0.5099,2.7614,0.1576
30.6400,0.5105,2.7648,0.1579
30.6800,0.5112,2.7687,0.1581
30.7200,0.5120,2.7744,0.1585
30.7600,0.5128,2.7811,0.1590
30.8000,0.5135,2.7870,0.1593
30.8400,0.5142,2.7917,0.1597
30.8800,0.5147,2.7959,0.1600
30.9200,0.5152,2.7996,0.1601
30.9600,0.5159,2.8030,0.1604
31.0000,0.5167,2.8080,0.1607
31.0400,0.5175,2.8147,0.1611
31.0800,0.5182,2.8204,0.1616
31.1200,0.5188,2.8250,0.1619
31.1600,0.5194,2.8295,0.1621
31.2000,0.5200,2.8335,0.1624
31.2400,0.5206,2.8372,0.1627
31.2800,0.5212,2.8412,0.1629
31.3200,0.5220,2.8463,0.1633
31.3600,0.5229,2.8529,0.1637
31.4000,0.5236,2.8591,0.1641
31.4400,0.5242,2.8645,0.1645
31.4800,0.5248,2.8689,0.1647
31.5200,0.5253,2.8724,0.1650
31.5600,0.5259,2.8758,0.1652
31.6000,0.5266,2.8799,0.1655
31.6400,0.5274,2.8859,0.1659
31.6800,0.5282,2.8924,0.1663
31.7200,0.5289,2.8977,0.1667
31.7600,0.5295,2.9024,0.1670
31.8000,0.5300,2.9068,0.1672
31.8400,0.5306,2.9107,0.1675
31.8800,0.5312,2.9145,0.1677
31.9200,0.5320,2.9191,0.1680
31.9600,0.5328,2.9255,0.1685
32.0000,0.5336,2.9321,0.1690
32.0400,0.5343,2.9377,0.1693
32.0800,0.5349,2.9422,0.1696
32.1200,0.5353,2.9458,0.1699
32.1600,0.5358,2.9488,0.1700
32.2000,0.5365,2.9527,0.1703
32.2400,0.5374,2.9582,0.1706
32.2800,0.5382,2.9652,0.1711
32.3200,0.5389,2.9710,0.1716
32.3600,0.5395,2.9758,0.1719
32.4000,0.5401,2.9802,0.1721
32.4400,0.5407,2.9842,0.1724
32.4800,0.5412,2.9881,0.1727
32.5200,0.5419,2.9924,0.1730
32.5600,0.5428,2.9983,0.1733
32.6000,0.5436,3.0049,0.1738
32.6400,0.5442,3.0101,0.1741
32.6800,0.5448,3.0144,0.1744
32.7200,0.5454,3.0184,0.1747
32.7600,0.5459,3.0222,0.1749
32.8000,0.5465,3.0259,0.1752
32.8400,0.5473,3.0306,0.1755
32.8800,0.5482,3.0374,0.1760
32.9200,0.5489,3.0438,0.1765
32.9600,0.5496,3.0492,0.1768
33.0000,0.5502,3.0540,0.1771
33.0400,0.5507,3.0577,0.1773
33.0800,0.5512,3.0614,0.1776
33.1200,0.5519,3.0651,0.1778
33.1600,0.5526,3.0700,0.1782
33.2000,0.5534,3.0766,0.1787
33.2400,0.5542,3.0823,0.1790
33.2800,0.5548,3.0873,0.1793
33.3200,0.5554,3.0918,0.1796
33.3600,0.5560,3.0955,0.1799
33.4000,0.5565,3.0991,0.1801
33.4400,0.5572,3.1036,0.1804
33.4800,0.5582,3.1098,0.1809
33.5200,0.5590,3.1170,0.1814
33.5600,0.5596,3.1224,0.1817
33.6000,0.5602,3.1270,0.1820
33.6400,0.5607,3.1310,0.1823
33.6800,0.5613,3.1344,0.1825
33.7200,0.5618,3.1377,0.1827
33.7600,0.5626,3.1423,0.1830
33.8000,0.5634,3.1484,0.1835
33.8400,0.5642,3.1547,0.1839
33.8800,0.5649,3.1603,0.1843
33.9200,0.5655,3.1649,0.1847
33.9600,0.5660,3.1691,0.1849
34.0000,0.5666,3.1727,0.1851
34.0400,0.5672,3.1765,0.1854
34.0800,0.5681,3.1825,0.1858
34.1200,0.5690,3.1897,0.1863
34.1600,0.5696,3.1958,0.1868
34.2000,0.5702,3.2002,0.1870
34.2400,0.5707,3.2042,0.1873
34.2800,0.5713,3.2079,0.1875
34.3200,0.5718,3.2114,0.1878
34.3600,0.5725,3.2155,0.1881
34.4000,0.5734,3.2214,0.1885
34.4400,0.5742,3.2284,0.1889
34.4800,0.5749,3.2342,0.1894
34.5200,0.5755,3.2392,0.1897
34.5600,0.5761,3.2435,0.1900
34.6000,0.5766,3.2469,0.1902
34.6400,0.5772,3.2506,0.1905
34.6800,0.5781,3.2559,0.1909
34.7200,0.5789,3.2627,0.1913
34.7600,0.5796,3.2688,0.1918
34.8000,0.5802,3.2731,0.1921
34.8400,0.5808,3.2773,0.1923
34.8800,0.5813,3.2812,0.1926
34.9200,0.5818,3.2851,0.1929
34.9600,0.5825,3.2891,0.1931
35.0000,0.5833,3.2944,0.1935
35.0400,0.5842,3.3014,0.1940
35.0800,0.5849,3.3079,0.1945
35.1200,0.5856,3.3131,0.1948
35.1600,0.5861,3.3175,0.1951
35.2000,0.5866,3.3210,0.1953
35.2400,0.5872,3.3243,0.1956
35.2800,0.5879,3.3289,0.1959
35.3200,0.5888,3.3349,0.1963
35.3600,0.5896,3.3413,0.1968
35.4000,0.5902,3.3464,0.1972
35.4400,0.5908,3.3510,0.1974
35.4800,0.5914,3.3551,0.1978
35.5200,0.5919,3.3591,0.1980
35.5600,0.5925,3.3629,0.1983
35.6000,0.5932,3.3676,0.1986
35.6400,0.5942,3.3742,0.1991
35.6800,0.5950,3.3813,0.1995
35.7200,0.5956,3.3866,0.2000
35.7600,0.5961,3.3907,0.2002
35.8000,0.5967,3.3945,0.2005
35.8400,0.5972,3.3979,0.2007
35.8800,0.5979,3.4018,0.2010
35.9200,0.5987,3.4072,0.2014
35.9600,0.5995,3.4139,0.2018
36.0000,0.6002,3.4198,0.2023
36.0400,0.6008,3.4245,0.2026
36.0800,0.6014,3.4291,0.2029
36.1200,0.6019,3.4331,0.2032
36.1600,0.6025,3.4367,0.2034
36.2000,0.6032,3.4412,0.2037
36.2400,0.6041,3.4472,0.2042
36.2800,0.6050,3.4541,0.2047
36.3200,0.6056,3.4598,0.2051
36.3600,0.6062,3.4638,0.2054
36.4000,0.6066,3.4674,0.2057
36.4400,0.6072,3.4711,0.2059
36.4800,0.6078,3.4748,0.2061
36.5200,0.6086,3.4800,0.2065
36.5600,0.6095,3.4870,0.2071
36.6000,0.6102,3.4936,0.2075
36.6400,0.6109,3.4987,0.2078
36.6520,0.6110,3.5000,0.2079