File: Nylon.csv
Specimen properties : Specimen label,Nylon 6,
Specimen text inputs : Specimen Name,Nylon 6,
Specimen properties : Length,100,mm
Specimen properties : Thickness,3,mm
Specimen properties : Width,10,mm
Test : Rate 1,20,mm/min
,,
Time,Displacement,Force
(s),(mm),(N)
0,0.0001,0.1737
0.36,0.1209,34.3804
0.72,0.2408,67.2705
1.08,0.3607,98.6502
1.44,0.481,128.9099
1.8,0.6008,158.3942
2.16,0.7205,187.0064
2.52,0.8408,214.9018
2.88,0.9607,241.9217
3.24,1.0806,268.1895
3.6,1.2009,293.6337
3.96,1.3206,318.2315
4.32,1.4406,342.0646
4.68,1.5606,364.9935
5.04,1.6805,387.2645
5.4,1.8002,408.6142
5.76,1.9205,429.2106
6.12,2.0402,449.1406
6.48,2.1601,468.0891
6.84,2.2802,486.2969
7.2,2.4002,503.6953
7.56,2.52,520.3331
7.92,2.6403,536.1864
8.28,2.7604,551.468
8.64,2.8803,565.8067
9,3.0005,579.5854
9.36,3.1204,592.6934
9.72,3.2404,605.2231
10.08,3.3605,617.0255
10.44,3.4804,628.3687
10.8,3.6002,639.1943
11.16,3.7204,649.5538
11.52,3.8403,659.4686
11.88,3.9603,668.9078
12.24,4.0807,678.1161
12.6,4.2005,686.8683
12.96,4.3208,695.3386
13.32,4.4409,703.2947
13.68,4.5608,711.1923
14.04,4.6808,718.7296
14.4,4.801,726.0035
14.76,4.9206,733.0737
15.12,5.0405,739.9698
15.48,5.1607,746.7642
15.84,5.2806,753.3484
16.2,5.4006,759.7007
16.56,5.5207,766.0514
16.92,5.6408,772.2271
17.28,5.761,778.1702
17.64,5.8811,784.0176
18,6.0011,789.857
18.36,6.1211,795.4686
18.72,6.2411,801.0332
19.08,6.3608,806.5181
19.44,6.4809,811.8807
19.8,6.6011,817.2131
20.16,6.7208,822.4471
20.52,6.8408,827.5958
20.88,6.9611,832.8119
21.24,7.081,837.9503
21.6,7.201,842.8895
21.96,7.3211,847.8694
22.32,7.4409,852.7841
22.68,7.5611,857.4947
23.04,7.681,862.2383
23.4,7.8009,866.9724
23.76,7.9208,871.5837
24.12,8.0408,876.1868
24.48,8.1605,880.7622
24.84,8.2807,885.2681
25.2,8.4006,889.7919
25.56,8.5205,894.2714
25.92,8.6405,898.6093
26.28,8.7607,902.9224
26.64,8.8806,907.2861
27,9.0007,911.4517
27.36,9.1207,915.6783
27.72,9.2404,919.9104
28.08,9.3603,924.0008
28.44,9.4804,928.1045
28.8,9.6002,932.1406
29.16,9.7202,936.0956
29.52,9.8403,940.1511
29.88,9.9601,944.0704
30.24,10.0803,947.9769
30.6,10.2006,951.9431
30.96,10.3204,955.7639
31.32,10.4406,959.4479
31.68,10.5607,963.265
32.04,10.6804,966.9745
32.4,10.8005,970.6378
32.76,10.9203,974.2073
33.12,11.0402,977.791
33.48,11.1604,981.3865
33.84,11.2803,984.9769
34.2,11.4004,988.5291
34.56,11.5207,992.0076
34.92,11.6407,995.5495
35.28,11.7606,998.8782
35.64,11.8811,1002.2337
36,12.0009,1005.502
36.36,12.1205,1008.7733
36.72,12.2409,1011.9824
37.08,12.3609,1015.2065
37.44,12.4804,1018.3482
37.8,12.6008,1021.582
38.16,12.7208,1024.7615
38.52,12.8405,1027.7754
38.88,12.9608,1030.777
39.24,13.0809,1033.8752
39.6,13.2006,1036.8076
39.96,13.321,1039.6733
40.32,13.4411,1042.6553
40.68,13.5612,1045.5497
41.04,13.6812,1048.2974
41.4,13.801,1051.0616
41.76,13.9208,1053.7606
42.12,14.0412,1056.5535
42.48,14.1609,1059.1519
42.84,14.2808,1061.8289
43.2,14.4009,1064.4679
43.56,14.5209,1067.1088
43.92,14.641,1069.6783
44.28,14.7611,1072.1813
44.64,14.881,1074.6415
45,15.0008,1077.073
45.36,15.1213,1079.4552
45.72,15.2409,1081.7666
46.08,15.3607,1084.0835
46.44,15.4807,1086.4185
46.8,15.6006,1088.7086
47.16,15.7204,1090.9092
47.52,15.8406,1093.1217
47.88,15.9606,1095.45
48.24,16.0802,1097.5721
48.6,16.2005,1099.6844
48.96,16.3206,1101.8018
49.32,16.4405,1103.8014
49.68,16.5605,1105.7727
50.04,16.6804,1107.7632
50.4,16.8002,1109.724
50.76,16.9203,1111.6792
51.12,17.04,1113.5558
51.48,17.1598,1115.3868
51.84,17.2804,1117.2963
52.2,17.4002,1119.1744
52.56,17.52,1120.9532
52.92,17.6403,1122.72
53.28,17.7603,1124.4852
53.64,17.8803,1126.2393
54,18.0008,1127.8613
54.36,18.1205,1129.5033
54.72,18.2406,1131.1593
55.08,18.3606,1132.7031
55.44,18.4804,1134.2904
55.8,18.6002,1135.7858
56.16,18.7207,1137.3967
56.52,18.8404,1138.9989
56.88,18.9604,1140.4122
57.24,19.0806,1141.8057
57.6,19.2008,1143.3615
57.96,19.321,1144.8019
58.32,19.441,1146.0417
58.68,19.5609,1147.4829
59.04,19.6809,1148.7607
59.4,19.8011,1150.1099
59.76,19.9208,1151.4333
60.12,20.0408,1152.6016
60.48,20.1609,1153.8995
60.84,20.2808,1155.1614
61.2,20.4007,1156.2489
61.56,20.521,1157.4629
61.92,20.6407,1158.6453
62.28,20.761,1159.7617
62.64,20.8814,1160.8304
63,21.001,1161.8995
63.36,21.1211,1162.9503
63.72,21.241,1164.0012
64.08,21.3608,1164.9998
64.44,21.4808,1165.8807
64.8,21.6011,1166.8998
65.16,21.7208,1167.8688
65.52,21.8409,1168.7809
65.88,21.9608,1169.7052
66.24,22.0806,1170.6498
66.6,22.2012,1171.5879
66.96,22.3211,1172.4094
67.32,22.4409,1173.2598
67.68,22.561,1174.0127
68.04,22.6811,1174.7999
68.4,22.8005,1175.526
68.76,22.9207,1176.3015
69.12,23.0405,1177.0708
69.48,23.1603,1177.824
69.84,23.2804,1178.5176
70.2,23.4004,1179.2439
70.56,23.5203,1180.0315
70.92,23.6404,1180.6349
71.28,23.7606,1181.324
71.64,23.8804,1181.9814
72,24.0006,1182.569
72.36,24.1206,1183.2235
72.72,24.2402,1183.7787
73.08,24.3603,1184.3016
73.44,24.4804,1184.8943
73.8,24.6001,1185.4343
74.16,24.7201,1185.9178
74.52,24.8402,1186.4751
74.88,24.9601,1187.1058
75.24,25.0804,1187.5355
75.6,25.2005,1188.0938
75.96,25.3204,1188.6154
76.32,25.4406,1189.0784
76.68,25.5607,1189.5149
77.04,25.6805,1189.9381
77.4,25.8006,1190.3171
77.76,25.9204,1190.7396
78.12,26.0402,1191.1591
78.48,26.1605,1191.5511
78.84,26.2806,1192.0009
79.2,26.4004,1192.4094
79.56,26.5208,1192.8203
79.92,26.6408,1193.2157
80.28,26.7605,1193.5436
80.64,26.8811,1193.8793
81,27.0011,1194.2452
81.36,27.1209,1194.4757
81.72,27.2411,1194.7992
82.08,27.3608,1195.0854
82.44,27.4807,1195.4763
82.8,27.6008,1195.6826
83.16,27.7207,1195.938
83.52,27.8406,1196.2167
83.88,27.9609,1196.4573
84.24,28.0808,1196.7501
84.6,28.2009,1196.9974
84.96,28.3212,1197.173
85.32,28.4411,1197.4634
85.68,28.5612,1197.6461
86.04,28.6812,1197.8341
86.4,28.8009,1198.0874
86.76,28.9209,1198.2168
87.12,29.0411,1198.3391
87.48,29.1609,1198.5754
87.84,29.2806,1198.7053
88.2,29.4007,1198.8286
88.56,29.5207,1199.0916
88.92,29.6408,1199.2991
89.28,29.761,1199.3956
89.64,29.8808,1199.5541
90,30.0009,1199.6545
90.36,30.1212,1199.7977
90.72,30.2408,1199.8745
91.08,30.3605,1199.9692
91.44,30.4806,1200.0759
91.8,30.6003,1200.2218
92.16,30.7202,1200.2828
92.52,30.8405,1200.3481
92.88,30.9603,1200.5116
93.24,31.0804,1200.5452
93.6,31.2007,1200.6204
93.96,31.3204,1200.6532
94.32,31.4405,1200.7318
94.68,31.5609,1200.7467
95.04,31.6803,1200.7919
95.4,31.8004,1200.7725
95.76,31.9202,1200.7916
96.12,32.0402,1200.8888
96.48,32.1599,1200.8298
96.84,32.2804,1200.8916
97.2,32.4001,1200.9312
97.56,32.5202,1201.015
97.92,32.6405,1201.0203
98.28,32.7605,1201.0791
98.64,32.8805,1201.0839
99,33.0008,1201.1044
99.36,33.1205,1201.0786
99.72,33.2407,1201.0623
100.08,33.3607,1201.0684
100.44,33.4804,1201.0837
100.8,33.6006,1201.1082
101.16,33.7207,1201.0637
101.52,33.8405,1201.1941
101.88,33.9608,1201.2028
102.24,34.0809,1201.2096
102.6,34.2008,1201.2156
102.96,34.321,1201.2173
103.32,34.4412,1201.1609
103.68,34.5609,1201.1329
104.04,34.6811,1201.0409
104.4,34.8011,1201.0594
104.76,34.9207,1201.0607
105.12,35.0408,1200.9666
105.48,35.1609,1200.9388
105.84,35.2805,1200.8969
106.2,35.4008,1200.8179
106.56,35.521,1200.7406
106.92,35.6407,1200.7323
107.28,35.761,1200.6804
107.64,35.8813,1200.6871
108,36.001,1200.5906
108.36,36.1212,1200.5137
108.72,36.2412,1200.4316
109.08,36.3609,1200.3806
109.44,36.481,1200.2611
109.8,36.6009,1200.1697
110.16,36.7205,1200.171
110.52,36.8408,1200.0515
110.88,36.9607,1200.0302
111.24,37.0807,1200.0229
111.6,37.2008,1199.9375
111.96,37.321,1199.8977
112.32,37.4407,1199.8314
112.68,37.561,1199.6906
113.04,37.6807,1199.6305
113.4,37.8004,1199.5183
113.76,37.9205,1199.3945
114.12,38.0403,1199.3646
114.48,38.1602,1199.3502
114.84,38.2802,1199.1671
115.2,38.4003,1199.1168
115.56,38.5201,1199.097
115.92,38.6404,1199.0277
116.28,38.7603,1198.9552
116.64,38.8802,1198.859
117,39.0007,1198.7401
117.36,39.1205,1198.6891
117.72,39.2404,1198.5905
118.08,39.3604,1198.402
118.44,39.4801,1198.3029
118.8,39.6001,1198.2357
119.16,39.7204,1198.0811
119.52,39.8403,1197.9575
119.88,39.9603,1197.9449
120.24,40.0804,1197.8563
120.6,40.2005,1197.7919
120.96,40.3207,1197.7552
121.32,40.441,1197.6731
121.68,40.5609,1197.5707
122.04,40.6805,1197.4512
122.4,40.8008,1197.3091
122.76,40.9205,1197.256
123.12,41.0404,1197.1824
123.48,41.1607,1197.089
123.84,41.2805,1197.0272
124.2,41.4005,1196.9957
124.56,41.521,1196.9316
124.92,41.6407,1196.7645
125.28,41.7608,1196.6801
125.64,41.8811,1196.6353
126,42.001,1196.4592
126.36,42.1209,1196.3253
126.72,42.241,1196.1642
127.08,42.3608,1196.1188
127.44,42.4808,1196.0079
127.8,42.6009,1195.903
128.16,42.7206,1195.8096
128.52,42.8408,1195.6989
128.88,42.961,1195.6216
129.24,43.0808,1195.5093
129.6,43.201,1195.4078
129.96,43.3213,1195.3226
130.32,43.4412,1195.2383
130.68,43.5611,1195.0924
131.04,43.6814,1194.9451
131.4,43.801,1194.8948
131.76,43.9207,1194.7612
132.12,44.0409,1194.6357
132.48,44.1608,1194.532
132.84,44.2806,1194.5079
133.2,44.4008,1194.447
133.56,44.5205,1194.3687
133.92,44.6406,1194.2595
134.28,44.7609,1194.2474
134.64,44.8807,1194.1239
135,45.0008,1193.9918
135.36,45.1208,1193.9014
135.72,45.2405,1193.7642
136.08,45.3605,1193.7166
136.44,45.4804,1193.5596
136.8,45.6003,1193.473
137.16,45.7201,1193.3868
137.52,45.8403,1193.3137
137.88,45.9602,1193.1805
138.24,46.0803,1193.1042
138.6,46.2004,1193.0367
138.96,46.3204,1192.9773
139.32,46.4405,1192.8307
139.68,46.5606,1192.7125
140.04,46.6801,1192.6605
140.4,46.8003,1192.4982
140.76,46.9203,1192.385
141.12,47.0402,1192.312
141.48,47.1601,1192.2106
141.84,47.2805,1192.1783
142.2,47.4002,1192.1246
142.56,47.5205,1192.1364
142.92,47.6405,1192.0789
143.28,47.7607,1192.0332
143.64,47.8808,1191.891
144,48.0011,1191.8307
144.36,48.1207,1191.7255
144.72,48.241,1191.6328
145.08,48.3609,1191.4987
145.44,48.4806,1191.4333
145.8,48.6008,1191.3549
146.16,48.7207,1191.2723
146.52,48.8404,1191.1593
146.88,48.9607,1191.0497
147.24,49.0809,1191.0439
147.6,49.2007,1190.9691
147.96,49.3211,1190.8877
148.32,49.4413,1190.8027
148.68,49.5608,1190.7343
149.04,49.6811,1190.64
149.4,49.801,1190.5331
149.76,49.9207,1190.4468
150.12,50.0409,1190.3827
150.48,50.161,1190.26
150.84,50.2807,1190.1689
151.2,50.401,1190.109
151.56,50.5209,1190.0668
151.92,50.6407,1189.9702
152.28,50.7612,1189.9165
152.64,50.8812,1189.837
153,51.0011,1189.7664
153.36,51.1212,1189.6416
153.72,51.2408,1189.5145
154.08,51.3608,1189.41
154.44,51.4808,1189.2943
154.8,51.6007,1189.194
155.16,51.7205,1189.1284
155.52,51.8409,1189.0278
155.88,51.9606,1188.9438
156.24,52.0803,1188.8823
156.6,52.2009,1188.7882
156.96,52.3207,1188.6229
157.32,52.4406,1188.5713
157.68,52.5608,1188.3691
158.04,52.6806,1188.3085
158.4,52.8003,1188.1447
158.76,52.9203,1187.993
159.12,53.0403,1187.9341
159.48,53.1597,1187.7919
159.84,53.2802,1187.7289
160.2,53.4002,1187.6327
160.56,53.52,1187.5114
160.92,53.6404,1187.4242
161.28,53.7605,1187.3304
161.64,53.8802,1187.1656
162,54.0006,1187.0718
162.36,54.1202,1186.9919
162.72,54.24,1186.9585
163.08,54.3603,1186.8265
163.44,54.4803,1186.8016
163.8,54.6003,1186.8115
164.16,54.7205,1186.7711
164.52,54.8403,1186.7008
164.88,54.9602,1186.6438
165.24,55.0805,1186.6437
165.6,55.2004,1186.6663
165.96,55.3206,1186.6388
166.32,55.441,1186.5725
166.68,55.5608,1186.5935
167.04,55.6808,1186.4827
167.4,55.8011,1186.4696
167.76,55.9208,1186.4648
168.12,56.0406,1186.4584
168.48,56.161,1186.4386
168.84,56.2806,1186.3927
169.2,56.4006,1186.3701
169.56,56.521,1186.3848
169.92,56.6408,1186.3556
170.28,56.761,1186.2587
170.64,56.8812,1186.2495
171,57.001,1186.2073
171.36,57.1211,1186.1553
171.72,57.2411,1186.0442
172.08,57.3607,1186.0454
172.44,57.4809,1185.9999
172.8,57.6011,1185.9213
173.16,57.7208,1185.8336
173.52,57.8408,1185.7881
173.88,57.9611,1185.7729
174.24,58.0808,1185.7715
174.6,58.2009,1185.7147
174.96,58.3212,1185.6975
175.32,58.441,1185.6276
175.68,58.5611,1185.4825
176.04,58.6812,1185.4205
176.4,58.8007,1185.2915
176.76,58.9207,1185.2369
177.12,59.0409,1185.1659
177.48,59.1605,1185.097
177.84,59.2804,1185.0443
178.2,59.4006,1184.9581
178.56,59.5203,1184.9841
178.92,59.6405,1184.9438
179.28,59.7609,1184.9503
179.64,59.8806,1184.9094
180,60.0007,1184.8127
180.36,60.1208,1184.8064
180.72,60.2404,1184.7705
181.08,60.3605,1184.8058
181.44,60.4806,1184.7719
181.8,60.6,1184.7294
182.16,60.7201,1184.6785
182.52,60.8403,1184.6791
182.88,60.9602,1184.7548
183.24,61.0802,1184.6652
183.6,61.2005,1184.7186
183.96,61.3203,1184.793
184.32,61.4405,1184.728
184.68,61.5606,1184.7397
185.04,61.6804,1184.7545
185.4,61.8003,1184.699
185.76,61.9205,1184.7056
186.12,62.0401,1184.6733
186.48,62.1604,1184.6844
186.84,62.2806,1184.7192
187.2,62.4003,1184.7368
187.56,62.5207,1184.7577
187.92,62.6407,1184.7919
188.28,62.7608,1184.7856
188.64,62.8809,1184.7487
189,63.0009,1184.6896
189.36,63.1208,1184.7668
189.72,63.2411,1184.7158
190.08,63.3606,1184.702
190.44,63.4803,1184.6423
190.8,63.6006,1184.7292
191.16,63.7206,1184.766
191.52,63.8405,1184.7827
191.88,63.9608,1184.7941
192.24,64.081,1184.8367
192.6,64.201,1184.8943
192.96,64.3214,1184.8235
193.32,64.4412,1184.8104
193.68,64.5609,1184.8525
194.04,64.6812,1184.8523
194.4,64.801,1184.8793
194.76,64.9209,1184.895
195.12,65.0409,1184.9127
195.48,65.1609,1184.9718
195.84,65.2808,1184.9525
196.2,65.4009,1184.9211
196.56,65.5208,1185.0082
196.92,65.6408,1185.0759
197.28,65.7611,1185.0997
197.64,65.8811,1185.0903
198,66.0008,1185.1072
198.36,66.1209,1185.0414
198.72,66.241,1185.038
199.08,66.3607,1184.9583
199.44,66.4807,1184.9429
199.8,66.6004,1184.9653
200.16,66.7203,1184.9152
200.52,66.8406,1184.915
200.88,66.9604,1184.9988
201.24,67.0802,1185.0186
201.6,67.2006,1184.9585
201.96,67.3206,1184.927
202.32,67.4406,1184.9626
202.68,67.5607,1184.8809
203.04,67.6804,1184.8418
203.4,67.8001,1184.8107
203.76,67.9203,1184.8175
204.12,68.0402,1184.7887
204.48,68.1601,1184.7494
204.84,68.2803,1184.7334
205.2,68.4002,1184.7317
205.56,68.5203,1184.7266
205.92,68.6404,1184.7146
206.28,68.7605,1184.7209
206.64,68.8804,1184.7377
207,69.0006,1184.675
207.36,69.1208,1184.694
207.72,69.2404,1184.6107
208.08,69.3606,1184.6469
208.44,69.4804,1184.635
208.8,69.6005,1184.6482
209.16,69.7205,1184.6808
209.52,69.8405,1184.7456
209.88,69.9604,1184.7773
210.24,70.0808,1184.8232
210.6,70.2008,1184.9056
210.96,70.3208,1184.9175
211.32,70.4411,1184.9404
211.68,70.561,1184.9781
212.04,70.681,1184.9285
212.4,70.801,1184.9303
212.76,70.9208,1184.967
213.12,71.0407,1184.9481
213.48,71.1609,1184.999
213.84,71.2806,1185.0157
214.2,71.4006,1184.9722
214.56,71.5208,1185.0294
214.92,71.6408,1185.0449
215.28,71.761,1185.0499
215.64,71.8812,1185.0361
216,72.0011,1185.1472
216.36,72.1212,1185.1058
216.72,72.2414,1185.1759
217.08,72.361,1185.1921
217.44,72.4809,1185.1617
217.8,72.601,1185.2556
218.16,72.7206,1185.2614
218.52,72.841,1185.3185
218.88,72.9609,1185.3815
219.24,73.0807,1185.4971
219.6,73.2008,1185.4999
219.96,73.3209,1185.553
220.32,73.4408,1185.5612
220.68,73.5609,1185.5609
221.04,73.6811,1185.5635
221.4,73.8005,1185.531
221.76,73.9207,1185.5376
222.12,74.0405,1185.519
222.48,74.1602,1185.5063
222.84,74.2803,1185.5278
223.2,74.4,1185.4724
223.56,74.5202,1185.5753
223.92,74.6405,1185.5759
224.28,74.7606,1185.5406
224.64,74.8805,1185.5868
225,75.0006,1185.6404
225.36,75.1205,1185.6101
225.72,75.24,1185.6844
226.08,75.3602,1185.7151
226.44,75.4803,1185.7955
226.8,75.5999,1185.8853
227.16,75.72,1185.941
227.52,75.8404,1186.0422
227.88,75.9601,1186.1688
228.24,76.0804,1186.2231
228.6,76.2004,1186.3497
228.96,76.3203,1186.4198
229.32,76.4407,1186.5502
229.68,76.5607,1186.603
230.04,76.6805,1186.6642
230.4,76.8006,1186.7402
230.76,76.9204,1186.7748
231.12,77.0405,1186.9202
231.48,77.1606,1187.0081
231.84,77.2805,1187.1213
232.2,77.4004,1187.2225
232.56,77.5206,1187.3601
232.92,77.6408,1187.5366
233.28,77.7607,1187.6752
233.64,77.8812,1187.7738
234,78.0011,1187.8582
234.36,78.1208,1187.9169
234.72,78.2408,1188.0125
235.08,78.3609,1188.1658
235.44,78.4807,1188.3351
235.8,78.6008,1188.4421
236.16,78.7207,1188.5795
236.52,78.8408,1188.7365
236.88,78.961,1188.796
237.24,79.0809,1188.9263
237.6,79.2007,1189.054
237.96,79.3212,1189.1321
238.32,79.4412,1189.2729
238.68,79.5609,1189.3331
239.04,79.6814,1189.4562
239.4,79.8011,1189.5735
239.76,79.921,1189.6904
240.12,80.0411,1189.7704
240.48,80.1608,1189.927
240.84,80.2807,1190.0646
241.2,80.4009,1190.2131
241.56,80.5208,1190.3613
241.92,80.6407,1190.5004
242.28,80.7611,1190.6178
242.64,80.8809,1190.673
243,81.0009,1190.731
243.36,81.121,1190.8368
243.72,81.2407,1190.921
244.08,81.3607,1191.0121
244.44,81.4808,1191.1017
244.8,81.6006,1191.2661
245.16,81.7203,1191.3224
245.52,81.8405,1191.4272
245.88,81.9603,1191.5492
246.24,82.0801,1191.6754
246.6,82.2005,1191.7837
246.96,82.3205,1191.8939
247.32,82.4404,1191.9821
247.68,82.5605,1192.1156
248.04,82.6805,1192.186
248.4,82.8002,1192.2832
248.76,82.9203,1192.3453
249.12,83.0401,1192.4591
249.48,83.16,1192.5085
249.84,83.2803,1192.6306
250.2,83.4002,1192.8497
250.56,83.5203,1193.0157
250.92,83.6406,1193.2063
251.28,83.7604,1193.3411
251.64,83.8805,1193.5483
252,84.0009,1193.698
252.36,84.1207,1193.8462
252.72,84.2405,1193.9637
253.08,84.3607,1194.1199
253.44,84.4805,1194.3264
253.8,84.6005,1194.4734
254.16,84.7206,1194.6139
254.52,84.8404,1194.8278
254.88,84.9607,1194.9916
255.24,85.0809,1195.1466
255.6,85.2008,1195.2974
255.96,85.3211,1195.4152
256.32,85.4414,1195.5227
256.68,85.5609,1195.6292
257.04,85.6811,1195.738
257.4,85.8009,1195.8478
257.76,85.9206,1196.002
258.12,86.0408,1196.1202
258.48,86.1608,1196.1851
258.84,86.2804,1196.3284
259.2,86.4009,1196.3909
259.56,86.5209,1196.4723
259.92,86.6407,1196.6403
260.28,86.7613,1196.7225
260.64,86.8813,1196.8534
261,87.0011,1196.9347
261.36,87.1212,1196.9866
261.72,87.2413,1197.1594
262.08,87.3609,1197.2345
262.44,87.481,1197.3031
262.8,87.6009,1197.4087
263.16,87.7207,1197.569
263.52,87.8408,1197.6223
263.88,87.9607,1197.7192
264.24,88.0805,1197.8927
264.6,88.2007,1198.0544
264.96,88.3209,1198.1925
265.32,88.4408,1198.2609
265.68,88.561,1198.4127
266.04,88.6808,1198.4932
266.4,88.8004,1198.6161
266.76,88.9205,1198.7191
267.12,89.0403,1198.9319
267.48,89.1601,1199.1802
267.84,89.2804,1199.3829
268.2,89.4006,1199.556
268.56,89.5201,1199.7612
268.92,89.6404,1199.9922
269.28,89.7606,1200.226
269.64,89.8804,1200.3634
270,90.0003,1200.5115
270.36,90.1205,1200.7882
270.72,90.2403,1200.958
271.08,90.3604,1201.118
271.44,90.4802,1201.3611
271.8,90.6,1201.5389
272.16,90.7204,1201.6991
272.52,90.8404,1201.8618
272.88,90.96,1202.05
273.24,91.0804,1202.2584
273.6,91.2006,1202.4386
273.96,91.3204,1202.5815
274.32,91.4409,1202.7223
274.68,91.5608,1202.8882
275.04,91.6806,1203.0601
275.4,91.8007,1203.1309
275.76,91.9208,1203.4017
276.12,92.0406,1203.5975
276.48,92.1608,1203.7866
276.84,92.2805,1203.97
277.2,92.4007,1204.2111
277.56,92.5207,1204.3811
277.92,92.641,1204.6442
278.28,92.7608,1204.7936
278.64,92.8811,1205.0012
279,93.0011,1205.188
279.36,93.1209,1205.3279
279.72,93.2412,1205.4934
280.08,93.3609,1205.653
280.44,93.4807,1205.7921
280.8,93.601,1205.9254
281.16,93.7206,1206.0116
281.52,93.8407,1206.2024
281.88,93.961,1206.3154
282.24,94.0809,1206.4557
282.6,94.201,1206.5785
282.96,94.3212,1206.686
283.32,94.4409,1206.8672
283.68,94.5612,1206.9418
284.04,94.6811,1207.0277
284.4,94.801,1207.1415
284.76,94.9208,1207.1702
285.12,95.0408,1207.2449
285.48,95.1608,1207.3252
285.84,95.2804,1207.3782
286.2,95.4007,1207.5005
286.56,95.5207,1207.6409
286.92,95.6403,1207.6846
287.28,95.761,1207.8538
287.64,95.8808,1207.9279
288,96.0009,1207.9969
288.36,96.1211,1208.1273
288.72,96.2405,1208.2568
289.08,96.3605,1208.4022
289.44,96.4805,1208.5267
289.8,96.6001,1208.6989
290.16,96.7201,1208.8324
290.52,96.8402,1209.0616
290.88,96.9601,1209.2213
291.24,97.0804,1209.4043
291.6,97.2004,1209.5764
291.96,97.3205,1209.8234
292.32,97.4406,1209.9886
292.68,97.5607,1210.2042
293.04,97.6803,1210.4628
293.4,97.8003,1210.6216
293.76,97.9203,1210.8087
294.12,98.0402,1211.0818
294.48,98.1602,1211.2146
294.84,98.2805,1211.3981
295.2,98.4003,1211.6523
295.56,98.5202,1211.8134
295.92,98.6406,1212.1028
296.28,98.7604,1212.3025
296.64,98.8807,1212.5271
297,99.0011,1212.7158
297.36,99.1208,1212.9209
297.72,99.2408,1213.0247
298.08,99.3607,1213.2622
298.44,99.4804,1213.4724
298.8,99.6007,1213.6801
299.16,99.7207,1213.9119
299.52,99.8405,1214.1788
299.88,99.9608,1214.3956
300.24,100.081,1214.6488
300.6,100.2008,1214.8638
300.96,100.3209,1215.047
301.32,100.4412,1215.2833
301.68,100.561,1215.5138
302.04,100.6812,1215.7415
302.4,100.801,1215.8823
302.76,100.9207,1216.1732
303.12,101.0408,1216.3934
303.48,101.161,1216.5992
303.84,101.2807,1216.8285
304.2,101.4008,1217.0518
304.56,101.5209,1217.3058
304.92,101.6409,1217.5331
305.28,101.7612,1217.7126
305.64,101.8811,1217.9418
306,102.001,1218.1521
306.36,102.1212,1218.3044
306.72,102.2412,1218.516
307.08,102.3608,1218.7341
307.44,102.4809,1218.9358
307.8,102.6006,1219.1599
308.16,102.7204,1219.3837
308.52,102.8408,1219.6378
308.88,102.9606,1219.9105
309.24,103.0804,1220.1487
309.6,103.2008,1220.3602
309.96,103.3209,1220.6041
310.32,103.4407,1220.8268
310.68,103.5608,1220.9839
311.04,103.6806,1221.2112
311.4,103.8002,1221.4291
311.76,103.9204,1221.6492
312.12,104.0403,1221.8966
312.48,104.1602,1222.1058
312.84,104.2802,1222.358
313.2,104.4002,1222.6224
313.56,104.5201,1222.8243
313.92,104.6403,1223.0984
314.28,104.7605,1223.4044
314.64,104.8802,1223.6117
315,105.0005,1223.9117
315.36,105.1205,1224.2084
315.72,105.2403,1224.469
316.08,105.3604,1224.6719
316.44,105.4804,1224.9531
316.8,105.6002,1225.2643
317.16,105.7206,1225.5698
317.52,105.8405,1225.8402
317.88,105.9603,1226.0562
318.24,106.0806,1226.3622
318.6,106.2006,1226.6681
318.96,106.3207,1226.8857
319.32,106.441,1227.1241
319.68,106.5608,1227.3862
320.04,106.6808,1227.5863
320.4,106.8009,1227.7722
320.76,106.9205,1228.0488
321.12,107.0406,1228.3293
321.48,107.1608,1228.5822
321.84,107.2807,1228.827
322.2,107.4007,1229.0459
322.56,107.521,1229.3027
322.92,107.6408,1229.5627
323.28,107.761,1229.7803
323.64,107.8813,1230.0087
324,108.0011,1230.3394
324.36,108.1209,1230.5266
324.72,108.2415,1230.8209
325.08,108.3609,1231.0879
325.44,108.481,1231.3773
325.8,108.6014,1231.6656
326.16,108.7209,1231.886
326.52,108.841,1232.0974
326.88,108.9611,1232.3821
327.24,109.0808,1232.6757
327.6,109.201,1232.912
327.96,109.3213,1233.199
328.32,109.441,1233.4608
328.68,109.5612,1233.7255
329.04,109.6812,1233.9045
329.4,109.8008,1234.1228
329.76,109.9208,1234.4265
330.12,110.0409,1234.7024
330.48,110.1604,1234.9509
330.84,110.2805,1235.2059
331.2,110.4007,1235.557
331.56,110.5205,1235.8702
331.92,110.6406,1236.0673
332.28,110.7608,1236.3134
332.64,110.8805,1236.5635
333,111.0008,1236.8088
333.36,111.1206,1236.9717
333.72,111.2402,1237.1862
334.08,111.3603,1237.444
334.44,111.4803,1237.6882
334.8,111.6,1237.9342
335.16,111.7202,1238.0891
335.52,111.8403,1238.342
335.88,111.9601,1238.5375
336.24,112.0803,1238.734
336.6,112.2005,1239.0192
336.96,112.3203,1239.2532
337.32,112.4406,1239.4294
337.68,112.5605,1239.6078
338.04,112.6803,1239.8574
338.4,112.8004,1240.0321
338.76,112.9206,1240.2914
339.12,113.0404,1240.4999
339.48,113.1604,1240.7532
339.84,113.2805,1241.014
340.2,113.4003,1241.2722
340.56,113.5204,1241.5537
340.92,113.6406,1241.8419
341.28,113.7606,1242.0886
341.64,113.881,1242.2682
342,114.001,1242.5139
342.36,114.1206,1242.7032
342.72,114.2409,1242.8921
343.08,114.3609,1243.077
343.44,114.4805,1243.2852
343.8,114.6009,1243.5051
344.16,114.7209,1243.704
344.52,114.8405,1243.9115
344.88,114.9608,1244.0739
345.24,115.0807,1244.3312
345.6,115.2008,1244.5228
345.96,115.3213,1244.6788
346.32,115.4411,1244.8544
346.68,115.561,1245.0807
347.04,115.6812,1245.2551
347.4,115.801,1245.4363
347.76,115.9207,1245.5708
348.12,116.041,1245.7389
348.48,116.1607,1245.9618
348.84,116.2808,1246.0818
349.2,116.401,1246.2642
349.56,116.5209,1246.507
349.92,116.641,1246.6971
350.28,116.7612,1246.8231
350.64,116.881,1246.9883
351,117.0011,1247.2205
351.36,117.1211,1247.3076
351.72,117.2408,1247.434
352.08,117.3607,1247.5746
352.44,117.4807,1247.7762
352.8,117.6006,1247.9126
353.16,117.7204,1248.0945
353.52,117.8407,1248.2147
353.88,117.9605,1248.3815
354.24,118.0805,1248.4924
354.6,118.2006,1248.5481
354.96,118.3207,1248.7053
355.32,118.4404,1248.7706
355.68,118.5608,1248.9028
356.04,118.6804,1248.9763
356.4,118.8004,1249.0592
356.76,118.9203,1249.1953
357.12,119.0402,1249.2974
357.48,119.16,1249.3623
357.84,119.28,1249.4326
358.2,119.4001,1249.5383
358.56,119.52,1249.6046
358.92,119.6406,1249.7682
359.28,119.7601,1249.8789
359.64,119.8803,1250.0243
360,120.0007,1250.1515
360.36,120.1207,1250.2909
360.72,120.2404,1250.3948
361.08,120.3606,1250.5109
361.44,120.4802,1250.64
361.8,120.6003,1250.783
362.16,120.7204,1250.9049
362.52,120.8405,1251.075
362.88,120.9607,1251.2686
363.24,121.0807,1251.4287
363.6,121.2008,1251.5515
363.96,121.3209,1251.7603
364.32,121.441,1251.8756
364.68,121.5607,1252.016
365.04,121.6809,1252.1671
365.4,121.801,1252.3181
365.76,121.9208,1252.4916
366.12,122.0406,1252.6516
366.48,122.1607,1252.8553
366.84,122.2805,1253.0409
367.2,122.4007,1253.2408
367.56,122.5209,1253.3807
367.92,122.6407,1253.559
368.28,122.761,1253.713
368.64,122.8813,1253.8613
369,123.0009,1253.9403
369.36,123.1211,1254.0521
369.72,123.2412,1254.1798
370.08,123.3608,1254.2535
370.44,123.4811,1254.3258
370.8,123.601,1254.4259
371.16,123.7207,1254.5549
371.52,123.8409,1254.6571
371.88,123.9608,1254.7628
372.24,124.0807,1254.9443
372.6,124.2008,1255.0657
372.96,124.3211,1255.1934
373.32,124.4407,1255.2758
373.68,124.5611,1255.3812
374.04,124.6812,1255.5203
374.4,124.8005,1255.548
374.76,124.9208,1255.6808
375.12,125.0405,1255.7729
375.48,125.1604,1255.9697
375.84,125.2803,1256.0212
376.2,125.4006,1256.2241
376.56,125.5201,1256.3765
376.92,125.6405,1256.4874
377.28,125.7605,1256.6633
377.64,125.8805,1256.8015
378,126.0007,1256.9617
378.36,126.1205,1257.1283
378.72,126.2402,1257.2959
379.08,126.3603,1257.4126
379.44,126.4804,1257.6191
379.8,126.6,1257.7522
380.16,126.7203,1257.8976
380.52,126.8403,1258.0437
380.88,126.9601,1258.2539
381.24,127.0805,1258.4064
381.6,127.2003,1258.5205
381.96,127.3204,1258.7003
382.32,127.4407,1258.8693
382.68,127.5607,1258.9989
383.04,127.6804,1259.1447
383.4,127.8005,1259.2572
383.76,127.9204,1259.3579
384.12,128.0402,1259.5011
384.48,128.1605,1259.6473
384.84,128.2804,1259.869
385.2,128.4005,1260.0621
385.56,128.5208,1260.224
385.92,128.641,1260.5095
386.28,128.7607,1260.6647
386.64,128.881,1260.8551
387,129.0011,1260.9983
387.36,129.1208,1261.1565
387.72,129.2413,1261.402
388.08,129.3609,1261.5046
388.44,129.4807,1261.7301
388.8,129.601,1261.9048
389.16,129.7208,1262.0834
389.52,129.8408,1262.2069
389.88,129.9611,1262.3197
390.24,130.0809,1262.4803
390.6,130.2009,1262.6117
390.96,130.3213,1262.7238
391.32,130.4411,1262.8586
391.68,130.5612,1263.0065
392.04,130.6815,1263.1721
392.4,130.801,1263.3304
392.76,130.9209,1263.3914
393.12,131.0409,1263.5599
393.48,131.1608,1263.7397
393.84,131.2806,1263.8962
394.2,131.4008,1264.0322
394.56,131.5206,1264.2046
394.92,131.6409,1264.4423
395.28,131.761,1264.573
395.64,131.8807,1264.7234
396,132.001,1264.8519
396.36,132.1209,1265.026
396.72,132.2408,1265.2017
397.08,132.3602,1265.3276
397.44,132.4806,1265.5363
397.8,132.6003,1265.7427
398.16,132.7203,1265.9164
398.52,132.8405,1266.0782
398.88,132.9603,1266.3325
399.24,133.0804,1266.5117
399.6,133.2005,1266.6779
399.96,133.3205,1266.8362
400.32,133.4404,1267.0371
400.68,133.5606,1267.158
401.04,133.6803,1267.2913
401.4,133.8001,1267.4655
401.76,133.9202,1267.522
402.12,134.0403,1267.7202
402.48,134.1602,1267.7378
402.84,134.2804,1267.8873
403.2,134.4001,1268.0045
403.56,134.52,1268.1201
403.92,134.6404,1268.2411
404.28,134.7604,1268.3743
404.64,134.8806,1268.5018
405,135.0006,1268.6301
405.36,135.1207,1268.7266
405.72,135.2404,1268.7614
406.08,135.3606,1268.8489
406.44,135.4804,1268.9485
406.8,135.6006,1269.0179
407.16,135.7207,1269.0803
407.52,135.8404,1269.1902
407.88,135.9604,1269.231
408.24,136.0807,1269.2909
408.6,136.2008,1269.3352
408.96,136.3211,1269.3286
409.32,136.4413,1269.3258
409.68,136.561,1269.3644
410.04,136.6812,1269.3402
410.4,136.8009,1269.3612
410.76,136.9207,1269.3586
411.12,137.041,1269.4402
411.48,137.1609,1269.4376
411.84,137.2806,1269.5094
412.2,137.4008,1269.6002
412.56,137.521,1269.6536
412.92,137.6407,1269.7177
413.28,137.7614,1269.8027
413.64,137.8814,1269.8099
414,138.0011,1269.908
414.36,138.1212,1269.9436
414.72,138.2413,1270.0216
415.08,138.3608,1270.0872
415.44,138.4812,1270.1376
415.8,138.6009,1270.1772
416.16,138.7207,1270.2954
416.52,138.8406,1270.2969
416.88,138.9606,1270.3671
417.24,139.0806,1270.4949
417.6,139.201,1270.5164
417.96,139.3211,1270.5995
418.32,139.4408,1270.6583
418.68,139.561,1270.6799
419.04,139.6807,1270.7046
419.4,139.8005,1270.793
419.76,139.9205,1270.8519
420.12,140.0403,1270.9476
420.48,140.1602,1271.1085
420.84,140.2803,1271.2271
421.2,140.4004,1271.3146
421.56,140.5201,1271.4257
421.92,140.6405,1271.5781
422.28,140.7603,1271.6387
422.64,140.8803,1271.7582
423,141.0006,1271.8525
423.36,141.1205,1271.9481
423.72,141.2402,1272.0359
424.08,141.3604,1272.0449
424.44,141.4802,1272.101
424.8,141.5999,1272.198
425.16,141.7202,1272.2303
425.52,141.8402,1272.2875
425.88,141.9601,1272.3945
426.24,142.0804,1272.4515
426.6,142.2006,1272.5494
426.96,142.3205,1272.5785
427.32,142.4409,1272.5898
427.68,142.5608,1272.6155
428.04,142.6806,1272.5309
428.4,142.8007,1272.5033
428.76,142.9207,1272.579
429.12,143.0406,1272.5889
429.48,143.1608,1272.5902
429.84,143.2807,1272.65
430.2,143.4004,1272.67
430.56,143.5209,1272.7283
430.92,143.6408,1272.8292
431.28,143.761,1272.8279
431.64,143.8814,1272.889
432,144.0009,1272.9414
432.36,144.1209,1272.986
432.72,144.241,1273.019
433.08,144.3608,1273.1298
433.44,144.4807,1273.2394
433.8,144.6009,1273.306
434.16,144.7207,1273.4443
434.52,144.8407,1273.5809
434.88,144.961,1273.7665
435.24,145.081,1273.9025
435.6,145.201,1274.0171
435.96,145.3213,1274.1914
436.32,145.4412,1274.4065
436.68,145.5611,1274.5425
437.04,145.6812,1274.6353
437.4,145.8008,1274.7827
437.76,145.9208,1274.851
438.12,146.0411,1274.9102
438.48,146.1607,1274.9769
438.84,146.2806,1275.1042
439.2,146.4008,1275.1858
439.56,146.5206,1275.2968
439.92,146.6404,1275.3167
440.28,146.7608,1275.4634
440.64,146.8809,1275.5076
441,147.0007,1275.5754
441.36,147.1207,1275.6718
441.72,147.2404,1275.7906
442.08,147.3605,1275.9277
442.44,147.4805,1276.0286
442.8,147.6004,1276.1715
443.16,147.7202,1276.28
443.52,147.8401,1276.3989
443.88,147.9602,1276.5236
444.24,148.0802,1276.657
444.6,148.2005,1276.816
444.96,148.3205,1276.9309
445.32,148.4407,1277.0695
445.68,148.5605,1277.1454
446.04,148.6803,1277.3812
446.4,148.8002,1277.4927
446.76,148.9203,1277.6379
447.12,149.0401,1277.8905
447.48,149.1602,1278.0089
447.84,149.2804,1278.2576
448.2,149.4002,1278.4535
448.56,149.5204,1278.6476
448.92,149.6407,1278.8402
449.28,149.7604,1279.0277
449.64,149.8808,1279.1697
450,150.0009,1279.3273
450.36,150.1207,1279.4982
450.72,150.2407,1279.6154
451.08,150.3608,1279.8423
451.44,150.4806,1280.0896
451.8,150.6006,1280.3239
452.16,150.7207,1280.6179
452.52,150.8404,1280.9083
452.88,150.9607,1281.219
453.24,151.081,1281.5575
453.6,151.2007,1281.8242
453.96,151.3211,1282.0758
454.32,151.4413,1282.3744
454.68,151.5609,1282.6396
455.04,151.681,1282.8975
455.4,151.8009,1283.1512
455.76,151.9207,1283.5275
456.12,152.0409,1283.7814
456.48,152.1608,1284.0688
456.84,152.2807,1284.3743
457.2,152.4008,1284.6686
457.56,152.521,1285.0107
457.92,152.6409,1285.3254
458.28,152.761,1285.6049
458.64,152.8812,1285.9219
459,153.001,1286.224
459.36,153.1212,1286.4794
459.72,153.2409,1286.7418
460.08,153.3606,1286.998
460.44,153.4809,1287.2482
460.8,153.6008,1287.5044
461.16,153.7204,1287.6951
461.52,153.8407,1287.8763
461.88,153.9607,1288.1456
462.24,154.0804,1288.3563
462.6,154.2008,1288.5284
462.96,154.3209,1288.7173
463.32,154.4407,1288.8693
463.68,154.5609,1289.0132
464.04,154.6807,1289.1798
464.4,154.8002,1289.3251
464.76,154.9205,1289.5522
465.12,155.0403,1289.7209
465.48,155.1599,1289.8969
465.84,155.2802,1290.0599
466.2,155.4002,1290.2571
466.56,155.52,1290.4257
466.92,155.6404,1290.6301
467.28,155.7605,1290.8579
467.64,155.8803,1291.0624
468,156.0005,1291.2001
468.36,156.1204,1291.4042
468.72,156.2402,1291.6364
469.08,156.3604,1291.7666
469.44,156.4802,1291.9333
469.8,156.6002,1292.1532
470.16,156.7205,1292.3618
470.52,156.8403,1292.5773
470.88,156.9601,1292.8359
471.24,157.0806,1293.1761
471.6,157.2006,1293.4628
471.96,157.3208,1293.7642
472.32,157.441,1293.9824
472.68,157.5609,1294.3191
473.04,157.6808,1294.6185
473.4,157.8009,1294.9296
473.76,157.9207,1295.3154
474.12,158.0406,1295.7137
474.48,158.1608,1296.0817
474.84,158.2807,1296.5854
475.2,158.4005,1296.9543
475.56,158.5208,1297.4163
475.92,158.6409,1297.879
476.28,158.7611,1298.2793
476.64,158.8811,1298.6443
477,159.0012,1299.0697
477.36,159.1213,1299.5356
477.72,159.2412,1299.9189
478.08,159.3607,1300.3799
478.44,159.4807,1300.8422
478.8,159.6009,1301.2562
479.16,159.7208,1301.6798
479.52,159.8408,1302.0516
479.88,159.961,1302.5869
480.24,160.0809,1303.0062
480.6,160.201,1303.4072
480.96,160.3212,1303.9143
481.32,160.441,1304.3771
481.68,160.5611,1304.7947
482.04,160.6812,1305.2299
482.4,160.8006,1305.6404
482.76,160.9204,1306.0544
483.12,161.0409,1306.4884
483.48,161.1603,1306.8867
483.84,161.2805,1307.2496
484.2,161.4006,1307.6842
484.56,161.5204,1308.0151
484.92,161.6404,1308.3263
485.28,161.7606,1308.6721
485.64,161.8806,1309.0436
486,162.0006,1309.2521
486.36,162.1207,1309.5551
486.72,162.2403,1309.8684
487.08,162.3604,1310.1685
487.44,162.4804,1310.4706
487.8,162.6,1310.7754
488.16,162.7201,1311.0704
488.52,162.8403,1311.3956
488.88,162.96,1311.6963
489.24,163.0804,1311.9744
489.6,163.2003,1312.3385
489.96,163.3202,1312.6436
490.32,163.4406,1312.8224
490.68,163.5605,1313.1155
491.04,163.6803,1313.343
491.4,163.8005,1313.5146
491.76,163.9206,1313.6643
492.12,164.04,1313.8331
492.48,164.1604,1314.0148
492.84,164.2805,1314.1747
493.2,164.4004,1314.3151
493.56,164.5205,1314.4724
493.92,164.6406,1314.6195
494.28,164.7607,1314.8452
494.64,164.8811,1314.9451
495,165.001,1315.0171
495.36,165.1207,1315.1335
495.72,165.2411,1315.2327
496.08,165.3609,1315.314
496.44,165.4805,1315.329
496.8,165.6009,1315.4156
497.16,165.7207,1315.4043
497.52,165.8405,1315.4016
497.88,165.9607,1315.3446
498.24,166.0808,1315.3885
498.6,166.2008,1315.4156
498.96,166.3211,1315.3264
499.32,166.4412,1315.3456
499.68,166.5609,1315.3369
500.04,166.6814,1315.3062
500.4,166.8012,1315.2511
500.76,166.9209,1315.1543
501.12,167.041,1315.157
501.48,167.1609,1315.1039
501.84,167.2808,1314.9966
502.2,167.401,1314.9742
502.56,167.5208,1314.9944
502.92,167.6406,1314.9789
503.28,167.7612,1314.8837
503.64,167.881,1314.8618
504,168.0009,1314.8473
504.36,168.1211,1314.7396
504.72,168.241,1314.6431
505.08,168.3605,1314.563
505.44,168.4808,1314.5209
505.8,168.6004,1314.4841
506.16,168.7204,1314.4663
506.52,168.8404,1314.4764
506.88,168.9604,1314.5614
507.24,169.0804,1314.6337
507.6,169.2006,1314.5948
507.96,169.3206,1314.6797
508.32,169.4405,1314.6636
508.68,169.5608,1314.6353
509.04,169.6805,1314.5819
509.4,169.8,1314.4442
509.76,169.9204,1314.361
510.12,170.0399,1314.1819
510.48,170.16,1314.0333
510.84,170.2801,1313.7305
511.2,170.3999,1313.4371
511.56,170.52,1313.093
511.92,170.6407,1312.7059
512.28,170.7605,1312.1594
512.64,170.8803,1311.5476
513,171.0006,1310.8558
513.36,171.1207,1310.0222
513.72,171.2404,1308.9891
514.08,171.3604,1307.8948
514.44,171.4803,1306.6405
514.8,171.6003,1305.1833
515.16,171.7206,1303.5449
515.52,171.8403,1301.6501
515.88,171.9604,1299.556
516.24,172.0807,1297.0917
516.6,172.2007,1294.218
516.96,172.3208,1290.8214
517.32,172.4411,1286.8396
517.68,172.5608,1282.0326
518.04,172.6809,1276.1339
518.4,172.801,1268.298
518.76,172.9207,1257.2809
519.12,173.0407,1240.0387
519.48,173.1607,1175.1746
519.64,173.217,735.3822