File: PMMA.csv
Specimen properties : Specimen label,PMMA,
Specimen text inputs : Specimen Name,PMMA,
Specimen properties : Length,100,mm
Specimen properties : Thickness,3,mm
Specimen properties : Width,10,mm
Test : Rate 1,2,mm/min
,,
Time,Displacement,Force
(s),(mm),(N)
0,0,-1.0713
0.04,0.0001,-1.0912
0.08,0.0002,-1.1333
0.12,0.0004,-1.0957
0.16,0.0006,-1.0727
0.2,0.0019,-0.8702
0.24,0.0051,0.9195
0.28,0.008,3.8043
0.32,0.0102,5.9552
0.36,0.0118,7.4936
0.4,0.0133,8.7216
0.44,0.0145,9.7357
0.48,0.0157,10.6899
0.52,0.0171,11.6241
0.56,0.0187,12.7202
0.6,0.0198,13.7354
0.64,0.0212,14.695
0.68,0.0227,15.8834
0.72,0.0242,16.9166
0.76,0.0255,18.0397
0.8,0.0268,19.1056
0.84,0.0281,19.9694
0.88,0.0293,20.9452
0.92,0.0306,21.8881
0.96,0.0318,22.7319
1,0.0332,23.6841
1.04,0.0347,24.8488
1.08,0.036,25.9468
1.12,0.0373,26.9462
1.16,0.0385,27.8111
1.2,0.0399,28.7417
1.24,0.0413,29.8952
1.28,0.0426,30.8578
1.32,0.044,31.7844
1.36,0.0455,32.8915
1.4,0.0469,33.9452
1.44,0.0483,35.0226
1.48,0.0496,35.9869
1.52,0.0509,36.8921
1.56,0.0522,37.8814
1.6,0.0535,38.8041
1.64,0.0547,39.7423
1.68,0.0561,40.6655
1.72,0.0575,41.6316
1.76,0.0588,42.6833
1.8,0.06,43.6266
1.84,0.0612,44.4331
1.88,0.0626,45.3429
1.92,0.064,46.4726
1.96,0.0653,47.3126
2,0.0667,48.3493
2.04,0.0682,49.5005
2.08,0.0695,50.4499
2.12,0.071,51.4877
2.16,0.0722,52.4786
2.2,0.0734,53.2374
2.24,0.0747,54.1927
2.28,0.076,55.1209
2.32,0.0772,55.9324
2.36,0.0786,56.8771
2.4,0.08,57.9152
2.44,0.0813,58.9372
2.48,0.0826,59.8616
2.52,0.0839,60.7282
2.56,0.0852,61.6583
2.6,0.0865,62.6713
2.64,0.088,63.6328
2.68,0.0895,64.5813
2.72,0.091,65.7048
2.76,0.0924,66.8325
2.8,0.0937,67.8191
2.84,0.0949,68.6554
2.88,0.0962,69.5076
2.92,0.0974,70.4332
2.96,0.0986,71.2147
3,0.1,72.0583
3.04,0.1013,72.9695
3.08,0.1027,74.0474
3.12,0.104,74.8985
3.16,0.1052,75.7358
3.2,0.1066,76.7428
3.24,0.108,77.5333
3.28,0.1094,78.6839
3.32,0.1107,79.7438
3.36,0.1122,80.4224
3.4,0.1137,81.7416
3.44,0.115,82.7105
3.48,0.1163,83.466
3.52,0.1175,84.4884
3.56,0.1188,85.2481
3.6,0.1201,86.0623
3.64,0.1212,87.0641
3.68,0.1225,87.8189
3.72,0.1238,88.7035
3.76,0.1253,89.7199
3.8,0.1267,90.7198
3.84,0.1279,91.5688
3.88,0.1292,92.3827
3.92,0.1305,93.2829
3.96,0.1319,94.2579
4,0.1332,95.2531
4.04,0.1347,96.1777
4.08,0.1362,97.2454
4.12,0.1377,98.3646
4.16,0.139,99.2725
4.2,0.1401,100.1474
4.24,0.1414,100.966
4.28,0.1426,101.7961
4.32,0.1439,102.6301
4.36,0.1452,103.4803
4.4,0.1465,104.4252
4.44,0.1479,105.3954
4.48,0.1492,106.3356
4.52,0.1505,107.1916
4.56,0.1518,108.0268
4.6,0.1532,109.0046
4.64,0.1545,109.9953
4.68,0.156,110.9168
4.72,0.1575,111.9169
4.76,0.1589,112.9741
4.8,0.1603,113.9376
4.84,0.1616,114.836
4.88,0.1628,115.6746
4.92,0.1641,116.4811
4.96,0.1654,117.4014
5,0.1667,118.2484
5.04,0.168,119.0935
5.08,0.1693,120.0641
5.12,0.1707,120.9928
5.16,0.1719,121.8921
5.2,0.1732,122.7249
5.24,0.1746,123.5932
5.28,0.176,124.5507
5.32,0.1773,125.5485
5.36,0.1786,126.3659
5.4,0.1802,127.3108
5.44,0.1816,128.3728
5.48,0.183,129.3875
5.52,0.1843,130.2922
5.56,0.1855,131.1344
5.6,0.1868,131.9254
5.64,0.1881,132.7813
5.68,0.1892,133.6361
5.72,0.1905,134.4058
5.76,0.192,135.3094
5.8,0.1933,136.2745
5.84,0.1946,137.0976
5.88,0.1959,137.9729
5.92,0.1972,138.8711
5.96,0.1987,139.8407
6,0.1999,140.7965
6.04,0.2014,141.6325
6.08,0.2029,142.7516
6.12,0.2044,143.7837
6.16,0.2057,144.7591
6.2,0.207,145.5912
6.24,0.2081,146.361
6.28,0.2094,147.1664
6.32,0.2107,147.9915
6.36,0.2119,148.8753
6.4,0.2133,149.7229
6.44,0.2147,150.6612
6.48,0.216,151.6308
6.52,0.2175,152.5227
6.56,0.2186,153.3811
6.6,0.2199,154.2322
6.64,0.2214,155.1268
6.68,0.2225,155.9978
6.72,0.2241,156.8794
6.76,0.2255,157.9397
6.8,0.227,159.0091
6.84,0.2283,159.9698
6.88,0.2296,160.8301
6.92,0.2308,161.5652
6.96,0.2321,162.3753
7,0.2334,163.2664
7.04,0.2347,164.122
7.08,0.236,165.0258
7.12,0.2373,165.9314
7.16,0.2386,166.8226
7.2,0.2399,167.6633
7.24,0.2412,168.4812
7.28,0.2426,169.3865
7.32,0.244,170.2866
7.36,0.2453,171.2359
7.4,0.2467,172.1287
7.44,0.2482,173.0959
7.48,0.2496,174.1537
7.52,0.2509,175.0564
7.56,0.252,175.8849
7.6,0.2533,176.6518
7.64,0.2546,177.4553
7.68,0.2558,178.3076
7.72,0.2571,179.099
7.76,0.2585,180.0037
7.8,0.2601,181.0287
7.84,0.2614,181.9389
7.88,0.2626,182.7902
7.92,0.2637,183.5977
7.96,0.2652,184.4029
8,0.2666,185.3692
8.04,0.2679,186.3043
8.08,0.2693,187.1521
8.12,0.2708,188.1484
8.16,0.2722,189.1315
8.2,0.2737,190.1037
8.24,0.2748,190.9822
8.28,0.2761,191.7308
8.32,0.2775,192.64
8.36,0.2787,193.5406
8.4,0.2799,194.246
8.44,0.2812,195.0749
8.48,0.2826,195.9958
8.52,0.2839,196.9417
8.56,0.2853,197.816
8.6,0.2865,198.6545
8.64,0.2879,199.4642
8.68,0.2892,200.4089
8.72,0.2905,201.2535
8.76,0.2921,202.1935
8.8,0.2936,203.2437
8.84,0.2949,204.2287
8.88,0.2963,205.0904
8.92,0.2974,205.906
8.96,0.2987,206.679
9,0.3001,207.5227
9.04,0.3014,208.4161
9.08,0.3027,209.2717
9.12,0.3041,210.1221
9.16,0.3055,211.0777
9.2,0.3068,211.9819
9.24,0.308,212.8464
9.28,0.3093,213.5867
9.32,0.3106,214.3924
9.36,0.3119,215.3297
9.4,0.3133,216.1521
9.44,0.3149,217.1496
9.48,0.3163,218.1916
9.52,0.3177,219.1247
9.56,0.319,220.039
9.6,0.32,220.8215
9.64,0.3213,221.5459
9.68,0.3228,222.3503
9.72,0.3238,223.1649
9.76,0.3252,223.9441
9.8,0.3268,224.9355
9.84,0.3282,225.9714
9.88,0.3295,226.8518
9.92,0.3307,227.6869
9.96,0.332,228.453
10,0.3334,229.3413
10.04,0.3347,230.3014
10.08,0.3361,231.142
10.12,0.3375,232.0687
10.16,0.3389,233.0312
10.2,0.3404,233.9686
10.24,0.3417,234.8481
10.28,0.3428,235.6488
10.32,0.344,236.3878
10.36,0.3454,237.2803
10.4,0.3466,238.0946
10.44,0.3479,238.8818
10.48,0.3493,239.761
10.52,0.3506,240.6534
10.56,0.3519,241.5389
10.6,0.3532,242.39
10.64,0.3545,243.1709
10.68,0.3561,244.0643
10.72,0.3572,245.0526
10.76,0.3585,245.8587
10.8,0.3601,246.7398
10.84,0.3616,247.7611
10.88,0.363,248.7439
10.92,0.3643,249.6437
10.96,0.3655,250.4254
11,0.3667,251.1192
11.04,0.368,251.9355
11.08,0.3692,252.682
11.12,0.3705,253.5106
11.16,0.3719,254.4224
11.2,0.3734,255.3808
11.24,0.3747,256.302
11.28,0.3759,257.1332
11.32,0.3772,257.8808
11.36,0.3785,258.6929
11.4,0.3798,259.6374
11.44,0.3812,260.455
11.48,0.3827,261.4421
11.52,0.3842,262.4239
11.56,0.3856,263.3307
11.6,0.3869,264.2255
11.64,0.3879,264.9588
11.68,0.3892,265.7104
11.72,0.3905,266.5695
11.76,0.3918,267.364
11.8,0.3932,268.2106
11.84,0.3947,269.1809
11.88,0.3961,270.1494
11.92,0.3974,271.0219
11.96,0.3986,271.7418
12,0.3999,272.5155
12.04,0.4013,273.4651
12.08,0.4026,274.4078
12.12,0.404,275.1981
12.16,0.4055,276.1365
12.2,0.4069,277.1668
12.24,0.4082,278.079
12.28,0.4095,278.9073
12.32,0.4107,279.5842
12.36,0.412,280.3622
12.4,0.4133,281.2021
12.44,0.4146,282.0137
12.48,0.416,282.8963
12.52,0.4174,283.8202
12.56,0.4189,284.7991
12.6,0.4202,285.664
12.64,0.4213,286.4327
12.68,0.4228,287.235
12.72,0.4242,288.1278
12.76,0.4254,289.0061
12.8,0.4268,289.8008
12.84,0.4283,290.7632
12.88,0.4296,291.715
12.92,0.431,292.5938
12.96,0.4322,293.3886
13,0.4334,294.0441
13.04,0.4348,294.8623
13.08,0.436,295.7466
13.12,0.4374,296.5448
13.16,0.4388,297.3763
13.2,0.4402,298.3465
13.24,0.4414,299.2087
13.28,0.4426,300.0071
13.32,0.4438,300.6922
13.36,0.4452,301.4849
13.4,0.4467,302.4378
13.44,0.448,303.3517
13.48,0.4494,304.214
13.52,0.451,305.2054
13.56,0.4525,306.2228
13.6,0.4538,307.1036
13.64,0.4549,307.9405
13.68,0.4559,308.5115
13.72,0.4573,309.231
13.76,0.4586,310.14
13.8,0.4601,310.982
13.84,0.4614,311.8475
13.88,0.4628,312.7315
13.92,0.4641,313.614
13.96,0.4654,314.4851
14,0.4667,315.2493
14.04,0.468,316.0416
14.08,0.4693,316.8945
14.12,0.4706,317.7093
14.16,0.472,318.5831
14.2,0.4735,319.5339
14.24,0.4748,320.4606
14.28,0.4762,321.3773
14.32,0.4774,322.2036
14.36,0.4786,322.9101
14.4,0.48,323.692
14.44,0.4813,324.5516
14.48,0.4826,325.3459
14.52,0.484,326.2444
14.56,0.4854,327.1843
14.6,0.4869,328.0761
14.64,0.488,328.8665
14.68,0.4892,329.5973
14.72,0.4906,330.3952
14.76,0.4919,331.2771
14.8,0.4932,332.1141
14.84,0.4948,333.0122
14.88,0.4962,334
14.92,0.4976,334.9406
14.96,0.499,335.8195
15,0.5001,336.5838
15.04,0.5014,337.2539
15.08,0.5026,338.0191
15.12,0.5037,338.8346
15.16,0.5052,339.6152
15.2,0.5066,340.4797
15.24,0.508,341.4444
15.28,0.5093,342.2744
15.32,0.5105,343.0446
15.36,0.5118,343.7961
15.4,0.5132,344.6778
15.44,0.5146,345.5998
15.48,0.5159,346.4449
15.52,0.5174,347.3633
15.56,0.5189,348.3304
15.6,0.5203,349.2865
15.64,0.5216,350.1012
15.68,0.5227,350.8702
15.72,0.524,351.5984
15.76,0.5253,352.4279
15.8,0.5266,353.2313
15.84,0.5279,354.0316
15.88,0.5294,354.9203
15.92,0.5307,355.813
15.96,0.532,356.6324
16,0.5331,357.4574
16.04,0.5346,358.2227
16.08,0.5361,359.124
16.12,0.5373,360.0114
16.16,0.5387,360.8619
16.2,0.5402,361.8169
16.24,0.5416,362.7719
16.28,0.5429,363.6805
16.32,0.5442,364.4638
16.36,0.5454,365.2152
16.4,0.5467,365.9416
16.44,0.548,366.7491
16.48,0.5493,367.5237
16.52,0.5506,368.3191
16.56,0.5521,369.2369
16.6,0.5534,370.1174
16.64,0.5547,370.9414
16.68,0.5559,371.726
16.72,0.5573,372.4844
16.76,0.5586,373.3819
16.8,0.5599,374.1553
16.84,0.5615,375.0437
16.88,0.563,376.1382
16.92,0.5644,377.1066
16.96,0.5657,377.9281
17,0.5669,378.695
17.04,0.5681,379.324
17.08,0.5694,380.1245
17.12,0.5707,380.9313
17.16,0.572,381.7008
17.2,0.5734,382.5473
17.24,0.5747,383.3785
17.28,0.576,384.2163
17.32,0.5773,385.0345
17.36,0.5785,385.7875
17.4,0.5799,386.6235
17.44,0.5814,387.5516
17.48,0.5826,388.4104
17.52,0.5841,389.2178
17.56,0.5857,390.2086
17.6,0.5871,391.1937
17.64,0.5884,392.061
17.68,0.5895,392.8259
17.72,0.5906,393.4506
17.76,0.5919,394.2109
17.8,0.5933,395.0384
17.84,0.5945,395.8658
17.88,0.5958,396.6714
17.92,0.5974,397.5334
17.96,0.5988,398.4787
18,0.6,399.3541
18.04,0.6013,400.0183
18.08,0.6026,400.8004
18.12,0.6039,401.6906
18.16,0.6052,402.4524
18.2,0.6066,403.2901
18.24,0.6081,404.3073
18.28,0.6096,405.2949
18.32,0.6109,406.201
18.36,0.6121,407.0117
18.4,0.6134,407.6779
18.44,0.6147,408.4618
18.48,0.616,409.2565
18.52,0.6173,410.0626
18.56,0.6186,410.8431
18.6,0.6199,411.6447
18.64,0.6213,412.5214
18.68,0.6226,413.3363
18.72,0.6238,414.1093
18.76,0.6252,414.8946
18.8,0.6266,415.8459
18.84,0.6279,416.6657
18.88,0.6295,417.5746
18.92,0.6309,418.4969
18.96,0.6323,419.3848
19,0.6336,420.2232
19.04,0.6347,420.9358
19.08,0.636,421.5568
19.12,0.6373,422.3363
19.16,0.6386,423.1577
19.2,0.6399,423.9842
19.24,0.6413,424.8495
19.28,0.6427,425.6825
19.32,0.644,426.5716
19.36,0.6452,427.3346
19.4,0.6466,428.0583
19.44,0.648,428.9497
19.48,0.6493,429.7851
19.52,0.6506,430.5819
19.56,0.6521,431.4391
19.6,0.6537,432.4435
19.64,0.655,433.3815
19.68,0.6563,434.2002
19.72,0.6575,434.8692
19.76,0.6587,435.5947
19.8,0.66,436.421
19.84,0.6612,437.1908
19.88,0.6626,437.9811
19.92,0.6639,438.8145
19.96,0.6654,439.6714
20,0.6667,440.5101
20.04,0.668,441.3389
20.08,0.6693,442.0714
20.12,0.6707,442.9637
20.16,0.672,443.8128
20.2,0.6735,444.6475
20.24,0.675,445.6263
20.28,0.6765,446.6173
20.32,0.6776,447.3863
20.36,0.6789,448.2
20.4,0.68,448.8613
20.44,0.6813,449.5652
20.48,0.6827,450.3619
20.52,0.684,451.1874
20.56,0.6853,451.9868
20.6,0.6867,452.8248
20.64,0.6881,453.7142
20.68,0.6896,454.589
20.72,0.6907,455.4109
20.76,0.692,456.1289
20.8,0.6933,456.9184
20.84,0.6945,457.7205
20.88,0.6959,458.4901
20.92,0.6975,459.4202
20.96,0.699,460.4099
21,0.7003,461.2491
21.04,0.7016,462.0455
21.08,0.7027,462.7035
21.12,0.7038,463.3104
21.16,0.7053,464.1281
21.2,0.7066,464.9691
21.24,0.708,465.8073
21.28,0.7093,466.6479
21.32,0.7107,467.4672
21.36,0.712,468.3086
21.4,0.7132,469.0712
21.44,0.7146,469.8085
21.48,0.716,470.6446
21.52,0.7173,471.5346
21.56,0.7187,472.3388
21.6,0.7203,473.2922
21.64,0.7216,474.22
21.68,0.7229,475.0454
21.72,0.7242,475.822
21.76,0.7252,476.4526
21.8,0.7266,477.1703
21.84,0.7279,477.9937
21.88,0.7292,478.8294
21.92,0.7306,479.6211
21.96,0.7321,480.53
22,0.7335,481.4296
22.04,0.7347,482.2451
22.08,0.7358,482.9544
22.12,0.7373,483.6827
22.16,0.7387,484.5395
22.2,0.7399,485.3465
22.24,0.7413,486.1176
22.28,0.7428,487.0258
22.32,0.7441,487.8922
22.36,0.7455,488.7576
22.4,0.7467,489.6178
22.44,0.748,490.282
22.48,0.7494,491.1083
22.52,0.7507,491.9156
22.56,0.7519,492.656
22.6,0.7533,493.3723
22.64,0.7547,494.2991
22.68,0.756,495.1494
22.72,0.7573,495.9566
22.76,0.7585,496.6885
22.8,0.7599,497.4283
22.84,0.7613,498.2979
22.88,0.7625,499.0821
22.92,0.7641,499.8938
22.96,0.7656,500.847
23,0.7669,501.7603
23.04,0.7682,502.5658
23.08,0.7694,503.3292
23.12,0.7707,503.9927
23.16,0.772,504.7388
23.2,0.7733,505.5429
23.24,0.7747,506.315
23.28,0.776,507.1586
23.32,0.7775,508.0416
23.36,0.7788,508.8975
23.4,0.78,509.6421
23.44,0.7812,510.3821
23.48,0.7826,511.111
23.52,0.784,512.0052
23.56,0.7852,512.7644
23.6,0.7868,513.6268
23.64,0.7883,514.592
23.68,0.7897,515.4947
23.72,0.7911,516.3406
23.76,0.7922,517.067
23.8,0.7935,517.711
23.84,0.7947,518.4962
23.88,0.7959,519.2764
23.92,0.7973,520.0038
23.96,0.7988,520.8929
24,0.8002,521.8293
24.04,0.8015,522.6602
24.08,0.8028,523.3741
24.12,0.804,524.086
24.16,0.8054,524.8876
24.2,0.8067,525.7293
24.24,0.808,526.4646
24.28,0.8095,527.3264
24.32,0.8109,528.2708
24.36,0.8123,529.142
24.4,0.8136,529.9461
24.44,0.8148,530.7089
24.48,0.8161,531.3883
24.52,0.8174,532.1759
24.56,0.8187,532.9722
24.6,0.82,533.7091
24.64,0.8213,534.5137
24.68,0.8227,535.3113
24.72,0.8239,536.1188
24.76,0.8252,536.8687
24.8,0.8265,537.5212
24.84,0.8279,538.3217
24.88,0.8293,539.2684
24.92,0.8306,540.0691
24.96,0.8321,540.9083
25,0.8336,541.8387
25.04,0.835,542.7697
25.08,0.8363,543.5874
25.12,0.8374,544.3025
25.16,0.8387,544.9019
25.2,0.8398,545.6123
25.24,0.8411,546.3989
25.28,0.8424,547.1836
25.32,0.8439,547.9329
25.36,0.8453,548.8091
25.4,0.8467,549.7046
25.44,0.8479,550.4268
25.48,0.8492,551.1507
25.52,0.8506,551.9745
25.56,0.8519,552.8505
25.6,0.8533,553.556
25.64,0.8548,554.504
25.68,0.8563,555.4514
25.72,0.8577,556.3138
25.76,0.859,557.1355
25.8,0.86,557.7495
25.84,0.8613,558.4197
25.88,0.8626,559.1824
25.92,0.8639,559.954
25.96,0.8653,560.7376
26,0.8668,561.5845
26.04,0.8681,562.476
26.08,0.8692,563.2554
26.12,0.8704,563.9142
26.16,0.8718,564.6187
26.2,0.8734,565.5027
26.24,0.8746,566.386
26.28,0.876,567.1179
26.32,0.8775,568.0247
26.36,0.8789,568.9648
26.4,0.8803,569.861
26.44,0.8815,570.6477
26.48,0.8827,571.2354
26.52,0.884,571.911
26.56,0.8852,572.6265
26.6,0.8865,573.3481
26.64,0.8879,574.17
26.68,0.8894,575.1133
26.72,0.8908,576.0175
26.76,0.8921,576.7793
26.8,0.8933,577.4551
26.84,0.8947,578.2092
26.88,0.8962,579.0261
26.92,0.8973,579.843
26.96,0.8986,580.5337
27,0.9002,581.4094
27.04,0.9016,582.3258
27.08,0.9029,583.1539
27.12,0.9042,583.993
27.16,0.9054,584.6325
27.2,0.9067,585.3259
27.24,0.908,586.0788
27.28,0.9093,586.8559
27.32,0.9107,587.6322
27.36,0.9121,588.5131
27.4,0.9135,589.3775
27.44,0.9147,590.1425
27.48,0.9159,590.8197
27.52,0.9173,591.5619
27.56,0.9187,592.3959
27.6,0.92,593.2263
27.64,0.9214,594.006
27.68,0.923,594.9313
27.72,0.9245,595.9044
27.76,0.9258,596.721
27.8,0.9269,597.4434
27.84,0.9282,597.9778
27.88,0.9295,598.7396
27.92,0.9307,599.5426
27.96,0.9319,600.2456
28,0.9333,600.972
28.04,0.9348,601.8173
28.08,0.9361,602.6568
28.12,0.9375,603.4696
28.16,0.9388,604.2311
28.2,0.94,604.9939
28.24,0.9413,605.7266
28.28,0.9426,606.4649
28.32,0.9441,607.3065
28.36,0.9455,608.246
28.4,0.9469,609.0845
28.44,0.9482,609.878
28.48,0.9494,610.6084
28.52,0.9507,611.2827
28.56,0.9519,611.928
28.6,0.9532,612.7297
28.64,0.9545,613.4758
28.68,0.9559,614.2553
28.72,0.9573,615.1059
28.76,0.9587,615.9633
28.8,0.9599,616.7082
28.84,0.9612,617.4018
28.88,0.9625,618.1641
28.92,0.9639,618.9948
28.96,0.9652,619.7304
29,0.9668,620.5674
29.04,0.9683,621.5475
29.08,0.9696,622.4183
29.12,0.971,623.1891
29.16,0.9721,623.9161
29.2,0.9732,624.5366
29.24,0.9745,625.2042
29.28,0.9758,625.9574
29.32,0.9771,626.6861
29.36,0.9787,627.5579
29.4,0.98,628.418
29.44,0.9814,629.2128
29.48,0.9826,629.9473
29.52,0.9839,630.6109
29.56,0.9853,631.4026
29.6,0.9866,632.2347
29.64,0.9879,632.9885
29.68,0.9894,633.8032
29.72,0.991,634.7684
29.76,0.9923,635.6225
29.8,0.9936,636.4039
29.84,0.9947,637.0639
29.88,0.996,637.703
29.92,0.9973,638.4905
29.96,0.9985,639.238
30,0.9999,639.9347
30.04,1.0013,640.756
30.08,1.0028,641.6327
30.12,1.0041,642.4369
30.16,1.0054,643.1893
30.2,1.0067,643.9013
30.24,1.008,644.6624
30.28,1.0093,645.4534
30.32,1.0107,646.1664
30.36,1.0122,647.1344
30.4,1.0136,648.0598
30.44,1.0149,648.8804
30.48,1.0162,649.5616
30.52,1.0174,650.2543
30.56,1.0187,650.9044
30.6,1.02,651.6259
30.64,1.0212,652.3895
30.68,1.0226,653.0757
30.72,1.024,653.9266
30.76,1.0254,654.7755
30.8,1.0268,655.6219
30.84,1.028,656.3434
30.88,1.0293,657.0364
30.92,1.0306,657.8004
30.96,1.0318,658.5197
31,1.0333,659.2792
31.04,1.035,660.29
31.08,1.0364,661.168
31.12,1.0376,661.9799
31.16,1.0389,662.6702
31.2,1.0401,663.3074
31.24,1.0415,664.0051
31.28,1.0428,664.8529
31.32,1.0441,665.6109
31.36,1.0455,666.3799
31.4,1.0469,667.1893
31.44,1.0482,667.9778
31.48,1.0495,668.748
31.52,1.0507,669.4481
31.56,1.0521,670.1736
31.6,1.0535,670.9786
31.64,1.0547,671.7513
31.68,1.0561,672.4488
31.72,1.0577,673.3369
31.76,1.059,674.1587
31.8,1.0603,674.9355
31.84,1.0614,675.6432
31.88,1.0626,676.2404
31.92,1.0639,676.9431
31.96,1.0653,677.7171
32,1.0665,678.5024
32.04,1.0678,679.1491
32.08,1.0692,679.9491
32.12,1.0708,680.855
32.16,1.0721,681.6134
32.2,1.0732,682.3006
32.24,1.0745,683.0067
32.28,1.076,683.8006
32.32,1.0771,684.5164
32.36,1.0786,685.2476
32.4,1.0801,686.174
32.44,1.0815,687.071
32.48,1.0829,687.884
32.52,1.0841,688.6822
32.56,1.0853,689.3077
32.6,1.0866,689.9328
32.64,1.0879,690.6895
32.68,1.0892,691.4384
32.72,1.0906,692.164
32.76,1.0919,692.9383
32.8,1.0933,693.7352
32.84,1.0945,694.475
32.88,1.0958,695.1577
32.92,1.0972,695.8899
32.96,1.0986,696.7486
33,1.0999,697.5386
33.04,1.1015,698.3699
33.08,1.103,699.3254
33.12,1.1043,700.1266
33.16,1.1056,700.8929
33.2,1.1068,701.5893
33.24,1.1081,702.1824
33.28,1.1094,702.9249
33.32,1.1107,703.6732
33.36,1.112,704.4042
33.4,1.1134,705.132
33.44,1.1148,705.9448
33.48,1.1161,706.7526
33.52,1.1173,707.4933
33.56,1.1186,708.1352
33.6,1.12,708.9048
33.64,1.1213,709.7233
33.68,1.1226,710.4268
33.72,1.1241,711.208
33.76,1.1257,712.1874
33.8,1.127,713.0642
33.84,1.1284,713.826
33.88,1.1294,714.4813
33.92,1.1307,715.0785
33.96,1.132,715.8295
34,1.1333,716.5599
34.04,1.1345,717.2184
34.08,1.1359,717.9675
34.12,1.1373,718.7726
34.16,1.1386,719.5494
34.2,1.1398,720.2549
34.24,1.1411,720.9402
34.28,1.1427,721.7394
34.32,1.1438,722.5425
34.36,1.1454,723.2661
34.4,1.147,724.1795
34.44,1.1484,725.1487
34.48,1.1496,725.8982
34.52,1.1509,726.5756
34.56,1.152,727.2045
34.6,1.1533,727.7998
34.64,1.1546,728.5433
34.68,1.1559,729.297
34.72,1.1573,730.0688
34.76,1.1587,730.8897
34.8,1.1601,731.7192
34.84,1.1614,732.5161
34.88,1.1626,733.2366
34.92,1.1639,733.8627
34.96,1.1653,734.5829
35,1.1666,735.3759
35.04,1.1679,736.0945
35.08,1.1696,736.9492
35.12,1.1711,737.8943
35.16,1.1724,738.727
35.2,1.1737,739.4489
35.24,1.1748,740.0776
35.28,1.1761,740.6603
35.32,1.1774,741.3692
35.36,1.1787,742.1313
35.4,1.18,742.8884
35.44,1.1813,743.6195
35.48,1.1826,744.3302
35.52,1.184,745.1099
35.56,1.1852,745.851
35.6,1.1866,746.5123
35.64,1.188,747.32
35.68,1.1893,748.1486
35.72,1.1907,748.8344
35.76,1.1922,749.7058
35.8,1.1935,750.6186
35.84,1.1948,751.3277
35.88,1.1961,752.015
35.92,1.1972,752.6259
35.96,1.1986,753.2866
36,1.1999,754.0801
36.04,1.2011,754.8016
36.08,1.2025,755.4241
36.12,1.2039,756.2279
36.16,1.2053,757.072
36.2,1.2066,757.8561
36.24,1.2078,758.4919
36.28,1.2091,759.1653
36.32,1.2107,759.9652
36.36,1.2118,760.761
36.4,1.2133,761.4662
36.44,1.2148,762.3193
36.48,1.2162,763.1581
36.52,1.2176,763.957
36.56,1.2188,764.7173
36.6,1.22,765.2567
36.64,1.2213,765.996
36.68,1.2226,766.7475
36.72,1.2239,767.3964
36.76,1.2252,768.0867
36.8,1.2267,768.8842
36.84,1.228,769.7279
36.88,1.2293,770.4786
36.92,1.2306,771.2018
36.96,1.2319,771.8767
37,1.2334,772.6818
37.04,1.2346,773.4293
37.08,1.2362,774.1554
37.12,1.2377,775.0692
37.16,1.239,775.9271
37.2,1.2403,776.6051
37.24,1.2415,777.2872
37.28,1.2427,777.881
37.32,1.244,778.5004
37.36,1.2452,779.2209
37.4,1.2465,779.9371
37.44,1.248,780.6986
37.48,1.2495,781.576
37.52,1.2508,782.3998
37.56,1.2521,783.0816
37.6,1.2534,783.7667
37.64,1.2547,784.4906
37.68,1.256,785.2117
37.72,1.2572,785.8701
37.76,1.2587,786.5911
37.8,1.2602,787.5403
37.84,1.2617,788.3783
37.88,1.263,789.0822
37.92,1.264,789.7837
37.96,1.2653,790.3934
38,1.2667,791.0637
38.04,1.2679,791.8104
38.08,1.2692,792.449
38.12,1.2706,793.2016
38.16,1.272,794.0616
38.2,1.2733,794.8478
38.24,1.2746,795.5086
38.28,1.2758,796.1061
38.32,1.2772,796.8663
38.36,1.2787,797.6903
38.4,1.28,798.4002
38.44,1.2815,799.2101
38.48,1.283,800.0598
38.52,1.2843,800.8586
38.56,1.2856,801.5979
38.6,1.2868,802.2836
38.64,1.288,802.8388
38.68,1.2894,803.5606
38.72,1.2906,804.2721
38.76,1.2919,804.9429
38.8,1.2934,805.7366
38.84,1.2948,806.5839
38.88,1.2962,807.3963
38.92,1.2974,808.1203
38.96,1.2987,808.7357
39,1.3,809.4197
39.04,1.3013,810.1512
39.08,1.3026,810.8055
39.12,1.304,811.535
39.16,1.3056,812.424
39.2,1.307,813.2299
39.24,1.3083,814.003
39.28,1.3095,814.6934
39.32,1.3108,815.2819
39.36,1.312,816.0057
39.4,1.3132,816.67
39.44,1.3147,817.339
39.48,1.316,818.0822
39.52,1.3174,818.8871
39.56,1.3187,819.6239
39.6,1.3199,820.3204
39.64,1.3212,820.9306
39.68,1.3226,821.6319
39.72,1.3239,822.4254
39.76,1.3252,823.1317
39.8,1.3267,823.8975
39.84,1.3281,824.7457
39.88,1.3295,825.5411
39.92,1.3308,826.2519
39.96,1.3319,826.8707
40,1.3332,827.3502
40.04,1.3345,828.0797
40.08,1.3358,828.7432
40.12,1.3372,829.334
40.148,1.3412,466.2924